package xolova.blued00r.divinerpg.generation.iceika;

import java.util.Random;
import net.minecraft.block.Block;
import net.minecraft.item.ItemStack;
import net.minecraft.world.World;
import net.minecraft.world.gen.feature.WorldGenerator;
import xolova.blued00r.divinerpg.DivineRPG;
import xolova.blued00r.divinerpg.entities.tileentities.TileEntityIceikaChest;

public class WorldGenDungeon2 extends WorldGenerator
{
    protected int[] GetValidSpawnBlocks()
    {
        return new int[] {DivineRPG.iceikaStone.blockID};
    }

    public boolean LocationIsValidSpawn(World var1, int var2, int var3, int var4)
    {
        int var5 = 0;

        for (int var6 = var1.getBlockId(var2, var3, var4); var6 != 0; var6 = var1.getBlockId(var2, var3 + var5, var4))
        {
            ++var5;
        }

        if (var5 > 3)
        {
            return false;
        }
        else
        {
            var3 += var5 - 1;
            int var7 = var1.getBlockId(var2, var3, var4);
            int var8 = var1.getBlockId(var2, var3 + 1, var4);
            int var9 = var1.getBlockId(var2, var3 - 1, var4);
            int[] var10 = this.GetValidSpawnBlocks();
            int var11 = var10.length;

            for (int var12 = 0; var12 < var11; ++var12)
            {
                int var13 = var10[var12];

                if (var8 != 0)
                {
                    return false;
                }

                if (var7 == var13)
                {
                    return true;
                }

                if (var7 == Block.snow.blockID && var9 == var13)
                {
                    return true;
                }
            }

            return false;
        }
    }

    public boolean generate(World var1, Random var2, int var3, int var4, int var5)
    {
        var1.setBlock(var3 + 0, var4 + 0, var5 + 0, DivineRPG.iceikaStoneBricks.blockID);
        var1.setBlock(var3 + 0, var4 + 0, var5 + 1, DivineRPG.iceikaStoneBricks.blockID);
        var1.setBlock(var3 + 0, var4 + 0, var5 + 2, DivineRPG.iceikaStoneBricks.blockID);
        var1.setBlock(var3 + 0, var4 + 0, var5 + 3, DivineRPG.iceikaStoneBricks.blockID);
        var1.setBlock(var3 + 0, var4 + 0, var5 + 4, DivineRPG.iceikaStoneBricks.blockID);
        var1.setBlock(var3 + 0, var4 + 0, var5 + 5, DivineRPG.iceikaStoneBricks.blockID);
        var1.setBlock(var3 + 0, var4 + 0, var5 + 6, DivineRPG.iceikaStoneBricks.blockID);
        var1.setBlock(var3 + 0, var4 + 0, var5 + 7, DivineRPG.iceikaStoneBricks.blockID);
        var1.setBlock(var3 + 0, var4 + 1, var5 + 0, DivineRPG.iceikaStoneBricks.blockID);
        var1.setBlock(var3 + 0, var4 + 1, var5 + 1, DivineRPG.iceikaStoneBricks.blockID);
        var1.setBlock(var3 + 0, var4 + 1, var5 + 2, DivineRPG.iceikaStoneBricks.blockID);
        var1.setBlock(var3 + 0, var4 + 1, var5 + 3, DivineRPG.iceikaStoneBricks.blockID);
        var1.setBlock(var3 + 0, var4 + 1, var5 + 4, DivineRPG.iceikaStoneBricks.blockID);
        var1.setBlock(var3 + 0, var4 + 1, var5 + 5, DivineRPG.iceikaStoneBricks.blockID);
        var1.setBlock(var3 + 0, var4 + 1, var5 + 6, DivineRPG.iceikaStoneBricks.blockID);
        var1.setBlock(var3 + 0, var4 + 1, var5 + 7, DivineRPG.iceikaStoneBricks.blockID);
        var1.setBlock(var3 + 0, var4 + 2, var5 + 0, DivineRPG.iceikaStoneBricks.blockID);
        var1.setBlock(var3 + 0, var4 + 2, var5 + 1, DivineRPG.iceikaStoneBricks.blockID);
        var1.setBlock(var3 + 0, var4 + 2, var5 + 2, DivineRPG.iceikaStoneBricks.blockID);
        var1.setBlock(var3 + 0, var4 + 2, var5 + 3, DivineRPG.iceikaStoneBricks.blockID);
        var1.setBlock(var3 + 0, var4 + 2, var5 + 4, DivineRPG.iceikaStoneBricks.blockID);
        var1.setBlock(var3 + 0, var4 + 2, var5 + 5, DivineRPG.iceikaStoneBricks.blockID);
        var1.setBlock(var3 + 0, var4 + 2, var5 + 6, DivineRPG.iceikaStoneBricks.blockID);
        var1.setBlock(var3 + 0, var4 + 2, var5 + 7, DivineRPG.iceikaStoneBricks.blockID);
        var1.setBlock(var3 + 0, var4 + 3, var5 + 0, DivineRPG.iceikaStoneBricks.blockID);
        var1.setBlock(var3 + 0, var4 + 3, var5 + 1, DivineRPG.iceikaStoneBricks.blockID);
        var1.setBlock(var3 + 0, var4 + 3, var5 + 2, DivineRPG.iceikaStoneBricks.blockID);
        var1.setBlock(var3 + 0, var4 + 3, var5 + 3, DivineRPG.iceikaStoneBricks.blockID);
        var1.setBlock(var3 + 0, var4 + 3, var5 + 4, DivineRPG.iceikaStoneBricks.blockID);
        var1.setBlock(var3 + 0, var4 + 3, var5 + 5, DivineRPG.iceikaStoneBricks.blockID);
        var1.setBlock(var3 + 0, var4 + 3, var5 + 6, DivineRPG.iceikaStoneBricks.blockID);
        var1.setBlock(var3 + 0, var4 + 3, var5 + 7, DivineRPG.iceikaStoneBricks.blockID);
        var1.setBlock(var3 + 1, var4 + 0, var5 + 0, DivineRPG.iceikaStoneBricks.blockID);
        var1.setBlock(var3 + 1, var4 + 0, var5 + 1, DivineRPG.iceikaMossyCobble.blockID);
        var1.setBlock(var3 + 1, var4 + 0, var5 + 2, DivineRPG.iceikaMossyCobble.blockID);
        var1.setBlock(var3 + 1, var4 + 0, var5 + 3, DivineRPG.iceikaMossyCobble.blockID);
        var1.setBlock(var3 + 1, var4 + 0, var5 + 4, DivineRPG.iceikaMossyCobble.blockID);
        var1.setBlock(var3 + 1, var4 + 0, var5 + 5, DivineRPG.iceikaMossyCobble.blockID);
        var1.setBlock(var3 + 1, var4 + 0, var5 + 6, DivineRPG.iceikaMossyCobble.blockID);
        var1.setBlock(var3 + 1, var4 + 0, var5 + 7, DivineRPG.iceikaStoneBricks.blockID);
        var1.setBlock(var3 + 1, var4 + 0, var5 + 13, DivineRPG.iceikaStoneBricks.blockID);
        var1.setBlock(var3 + 1, var4 + 0, var5 + 14, DivineRPG.iceikaStoneBricks.blockID);
        var1.setBlock(var3 + 1, var4 + 0, var5 + 15, DivineRPG.iceikaStoneBricks.blockID);
        var1.setBlock(var3 + 1, var4 + 0, var5 + 16, DivineRPG.iceikaStoneBricks.blockID);
        var1.setBlock(var3 + 1, var4 + 0, var5 + 17, DivineRPG.iceikaStoneBricks.blockID);
        var1.setBlock(var3 + 1, var4 + 0, var5 + 18, DivineRPG.iceikaStoneBricks.blockID);
        var1.setBlock(var3 + 1, var4 + 0, var5 + 19, DivineRPG.iceikaStoneBricks.blockID);
        var1.setBlock(var3 + 1, var4 + 0, var5 + 20, DivineRPG.iceikaStoneBricks.blockID);
        var1.setBlock(var3 + 1, var4 + 1, var5 + 0, DivineRPG.iceikaStoneBricks.blockID);
        var1.setBlockWithNotify(var3 + 1, var4 + 1, var5 + 1, DivineRPG.iceikaChest.blockID);
        var1.setBlock(var3 + 1, var4 + 1, var5 + 2, 0);
        var1.setBlock(var3 + 1, var4 + 1, var5 + 3, 0);
        var1.setBlock(var3 + 1, var4 + 1, var5 + 4, 0);
        var1.setBlock(var3 + 1, var4 + 1, var5 + 5, 0);
        var1.setBlockWithNotify(var3 + 1, var4 + 1, var5 + 6, DivineRPG.iceikaChest.blockID);
        var1.setBlock(var3 + 1, var4 + 1, var5 + 7, DivineRPG.iceikaStoneBricks.blockID);
        var1.setBlock(var3 + 1, var4 + 1, var5 + 13, DivineRPG.iceikaStoneBricks.blockID);
        var1.setBlock(var3 + 1, var4 + 1, var5 + 14, DivineRPG.iceikaStoneBricks.blockID);
        var1.setBlock(var3 + 1, var4 + 1, var5 + 15, DivineRPG.iceikaStoneBricks.blockID);
        var1.setBlock(var3 + 1, var4 + 1, var5 + 16, DivineRPG.iceikaStoneBricks.blockID);
        var1.setBlock(var3 + 1, var4 + 1, var5 + 17, DivineRPG.iceikaStoneBricks.blockID);
        var1.setBlock(var3 + 1, var4 + 1, var5 + 18, DivineRPG.iceikaStoneBricks.blockID);
        var1.setBlock(var3 + 1, var4 + 1, var5 + 19, DivineRPG.iceikaStoneBricks.blockID);
        var1.setBlock(var3 + 1, var4 + 1, var5 + 20, DivineRPG.iceikaStoneBricks.blockID);
        var1.setBlock(var3 + 1, var4 + 2, var5 + 0, DivineRPG.iceikaStoneBricks.blockID);
        var1.setBlock(var3 + 1, var4 + 2, var5 + 1, 0);
        var1.setBlock(var3 + 1, var4 + 2, var5 + 2, 0);
        var1.setBlock(var3 + 1, var4 + 2, var5 + 3, 0);
        var1.setBlock(var3 + 1, var4 + 2, var5 + 4, 0);
        var1.setBlock(var3 + 1, var4 + 2, var5 + 5, 0);
        var1.setBlock(var3 + 1, var4 + 2, var5 + 6, 0);
        var1.setBlock(var3 + 1, var4 + 2, var5 + 7, DivineRPG.iceikaStoneBricks.blockID);
        var1.setBlock(var3 + 1, var4 + 2, var5 + 13, DivineRPG.iceikaStoneBricks.blockID);
        var1.setBlock(var3 + 1, var4 + 2, var5 + 14, DivineRPG.iceikaStoneBricks.blockID);
        var1.setBlock(var3 + 1, var4 + 2, var5 + 15, DivineRPG.iceikaStoneBricks.blockID);
        var1.setBlock(var3 + 1, var4 + 2, var5 + 16, DivineRPG.iceikaStoneBricks.blockID);
        var1.setBlock(var3 + 1, var4 + 2, var5 + 17, DivineRPG.iceikaStoneBricks.blockID);
        var1.setBlock(var3 + 1, var4 + 2, var5 + 18, DivineRPG.iceikaStoneBricks.blockID);
        var1.setBlock(var3 + 1, var4 + 2, var5 + 19, DivineRPG.iceikaStoneBricks.blockID);
        var1.setBlock(var3 + 1, var4 + 2, var5 + 20, DivineRPG.iceikaStoneBricks.blockID);
        var1.setBlock(var3 + 1, var4 + 3, var5 + 0, DivineRPG.iceikaStoneBricks.blockID);
        var1.setBlock(var3 + 1, var4 + 3, var5 + 1, 0);
        var1.setBlock(var3 + 1, var4 + 3, var5 + 2, 0);
        var1.setBlock(var3 + 1, var4 + 3, var5 + 3, 0);
        var1.setBlock(var3 + 1, var4 + 3, var5 + 4, 0);
        var1.setBlock(var3 + 1, var4 + 3, var5 + 5, 0);
        var1.setBlock(var3 + 1, var4 + 3, var5 + 6, 0);
        var1.setBlock(var3 + 1, var4 + 3, var5 + 7, DivineRPG.iceikaStoneBricks.blockID);
        var1.setBlock(var3 + 1, var4 + 3, var5 + 13, DivineRPG.iceikaStoneBricks.blockID);
        var1.setBlock(var3 + 1, var4 + 3, var5 + 14, DivineRPG.iceikaStoneBricks.blockID);
        var1.setBlock(var3 + 1, var4 + 3, var5 + 15, DivineRPG.iceikaStoneBricks.blockID);
        var1.setBlock(var3 + 1, var4 + 3, var5 + 16, DivineRPG.iceikaStoneBricks.blockID);
        var1.setBlock(var3 + 1, var4 + 3, var5 + 17, DivineRPG.iceikaStoneBricks.blockID);
        var1.setBlock(var3 + 1, var4 + 3, var5 + 18, DivineRPG.iceikaStoneBricks.blockID);
        var1.setBlock(var3 + 1, var4 + 3, var5 + 19, DivineRPG.iceikaStoneBricks.blockID);
        var1.setBlock(var3 + 1, var4 + 3, var5 + 20, DivineRPG.iceikaStoneBricks.blockID);
        var1.setBlock(var3 + 1, var4 + 4, var5 + 1, DivineRPG.iceikaStoneBricks.blockID);
        var1.setBlock(var3 + 1, var4 + 4, var5 + 2, DivineRPG.iceikaStoneBricks.blockID);
        var1.setBlock(var3 + 1, var4 + 4, var5 + 3, DivineRPG.iceikaStoneBricks.blockID);
        var1.setBlock(var3 + 1, var4 + 4, var5 + 4, DivineRPG.iceikaStoneBricks.blockID);
        var1.setBlock(var3 + 1, var4 + 4, var5 + 5, DivineRPG.iceikaStoneBricks.blockID);
        var1.setBlock(var3 + 1, var4 + 4, var5 + 6, DivineRPG.iceikaStoneBricks.blockID);
        var1.setBlock(var3 + 2, var4 + 0, var5 + 0, DivineRPG.iceikaStoneBricks.blockID);
        var1.setBlock(var3 + 2, var4 + 0, var5 + 1, DivineRPG.iceikaMossyCobble.blockID);
        var1.setBlock(var3 + 2, var4 + 0, var5 + 2, DivineRPG.iceikaMossyCobble.blockID);
        var1.setBlock(var3 + 2, var4 + 0, var5 + 3, DivineRPG.iceikaMossyCobble.blockID);
        var1.setBlock(var3 + 2, var4 + 0, var5 + 4, DivineRPG.iceikaMossyCobble.blockID);
        var1.setBlock(var3 + 2, var4 + 0, var5 + 5, DivineRPG.iceikaMossyCobble.blockID);
        var1.setBlock(var3 + 2, var4 + 0, var5 + 6, DivineRPG.iceikaMossyCobble.blockID);
        var1.setBlock(var3 + 2, var4 + 0, var5 + 7, DivineRPG.iceikaStoneBricks.blockID);
        var1.setBlock(var3 + 2, var4 + 0, var5 + 13, DivineRPG.iceikaStoneBricks.blockID);
        var1.setBlock(var3 + 2, var4 + 0, var5 + 14, DivineRPG.iceikaMossyCobble.blockID);
        var1.setBlock(var3 + 2, var4 + 0, var5 + 15, DivineRPG.iceikaMossyCobble.blockID);
        var1.setBlock(var3 + 2, var4 + 0, var5 + 16, DivineRPG.iceikaMossyCobble.blockID);
        var1.setBlock(var3 + 2, var4 + 0, var5 + 17, DivineRPG.iceikaMossyCobble.blockID);
        var1.setBlock(var3 + 2, var4 + 0, var5 + 18, DivineRPG.iceikaMossyCobble.blockID);
        var1.setBlock(var3 + 2, var4 + 0, var5 + 19, DivineRPG.iceikaMossyCobble.blockID);
        var1.setBlock(var3 + 2, var4 + 0, var5 + 20, DivineRPG.iceikaStoneBricks.blockID);
        var1.setBlock(var3 + 2, var4 + 1, var5 + 0, DivineRPG.iceikaStoneBricks.blockID);
        var1.setBlock(var3 + 2, var4 + 1, var5 + 1, 0);
        var1.setBlock(var3 + 2, var4 + 1, var5 + 2, 0);
        var1.setBlock(var3 + 2, var4 + 1, var5 + 3, 0);
        var1.setBlock(var3 + 2, var4 + 1, var5 + 4, 0);
        var1.setBlock(var3 + 2, var4 + 1, var5 + 5, 0);
        var1.setBlock(var3 + 2, var4 + 1, var5 + 6, 0);
        var1.setBlock(var3 + 2, var4 + 1, var5 + 7, DivineRPG.iceikaStoneBricks.blockID);
        var1.setBlock(var3 + 2, var4 + 1, var5 + 13, DivineRPG.iceikaStoneBricks.blockID);
        var1.setBlock(var3 + 2, var4 + 1, var5 + 14, 0);
        var1.setBlock(var3 + 2, var4 + 1, var5 + 15, 0);
        var1.setBlock(var3 + 2, var4 + 1, var5 + 16, 0);
        var1.setBlock(var3 + 2, var4 + 1, var5 + 17, 0);
        var1.setBlock(var3 + 2, var4 + 1, var5 + 18, 0);
        var1.setBlock(var3 + 2, var4 + 1, var5 + 19, 0);
        var1.setBlock(var3 + 2, var4 + 1, var5 + 20, DivineRPG.iceikaStoneBricks.blockID);
        var1.setBlock(var3 + 2, var4 + 2, var5 + 0, DivineRPG.iceikaStoneBricks.blockID);
        var1.setBlock(var3 + 2, var4 + 2, var5 + 1, 0);
        var1.setBlock(var3 + 2, var4 + 2, var5 + 2, 0);
        var1.setBlock(var3 + 2, var4 + 2, var5 + 3, 0);
        var1.setBlock(var3 + 2, var4 + 2, var5 + 4, 0);
        var1.setBlock(var3 + 2, var4 + 2, var5 + 5, 0);
        var1.setBlock(var3 + 2, var4 + 2, var5 + 6, 0);
        var1.setBlock(var3 + 2, var4 + 2, var5 + 7, DivineRPG.iceikaStoneBricks.blockID);
        var1.setBlock(var3 + 2, var4 + 2, var5 + 13, DivineRPG.iceikaStoneBricks.blockID);
        var1.setBlock(var3 + 2, var4 + 2, var5 + 14, 0);
        var1.setBlock(var3 + 2, var4 + 2, var5 + 15, 0);
        var1.setBlock(var3 + 2, var4 + 2, var5 + 16, 0);
        var1.setBlock(var3 + 2, var4 + 2, var5 + 17, 0);
        var1.setBlock(var3 + 2, var4 + 2, var5 + 18, 0);
        var1.setBlock(var3 + 2, var4 + 2, var5 + 19, 0);
        var1.setBlock(var3 + 2, var4 + 2, var5 + 20, DivineRPG.iceikaStoneBricks.blockID);
        var1.setBlock(var3 + 2, var4 + 3, var5 + 0, DivineRPG.iceikaStoneBricks.blockID);
        var1.setBlock(var3 + 2, var4 + 3, var5 + 1, 0);
        var1.setBlock(var3 + 2, var4 + 3, var5 + 2, 0);
        var1.setBlock(var3 + 2, var4 + 3, var5 + 3, 0);
        var1.setBlock(var3 + 2, var4 + 3, var5 + 4, 0);
        var1.setBlock(var3 + 2, var4 + 3, var5 + 5, 0);
        var1.setBlock(var3 + 2, var4 + 3, var5 + 6, 0);
        var1.setBlock(var3 + 2, var4 + 3, var5 + 7, DivineRPG.iceikaStoneBricks.blockID);
        var1.setBlock(var3 + 2, var4 + 3, var5 + 13, DivineRPG.iceikaStoneBricks.blockID);
        var1.setBlock(var3 + 2, var4 + 3, var5 + 14, 0);
        var1.setBlock(var3 + 2, var4 + 3, var5 + 15, 0);
        var1.setBlock(var3 + 2, var4 + 3, var5 + 16, 0);
        var1.setBlock(var3 + 2, var4 + 3, var5 + 17, 0);
        var1.setBlock(var3 + 2, var4 + 3, var5 + 18, 0);
        var1.setBlock(var3 + 2, var4 + 3, var5 + 19, 0);
        var1.setBlock(var3 + 2, var4 + 3, var5 + 20, DivineRPG.iceikaStoneBricks.blockID);
        var1.setBlock(var3 + 2, var4 + 4, var5 + 1, DivineRPG.iceikaStoneBricks.blockID);
        var1.setBlock(var3 + 2, var4 + 4, var5 + 2, DivineRPG.iceikaStoneBricks.blockID);
        var1.setBlock(var3 + 2, var4 + 4, var5 + 3, DivineRPG.iceikaStoneBricks.blockID);
        var1.setBlock(var3 + 2, var4 + 4, var5 + 4, DivineRPG.iceikaStoneBricks.blockID);
        var1.setBlock(var3 + 2, var4 + 4, var5 + 5, DivineRPG.iceikaStoneBricks.blockID);
        var1.setBlock(var3 + 2, var4 + 4, var5 + 6, DivineRPG.iceikaStoneBricks.blockID);
        var1.setBlock(var3 + 2, var4 + 4, var5 + 14, DivineRPG.iceikaStoneBricks.blockID);
        var1.setBlock(var3 + 2, var4 + 4, var5 + 15, DivineRPG.iceikaStoneBricks.blockID);
        var1.setBlock(var3 + 2, var4 + 4, var5 + 16, DivineRPG.iceikaStoneBricks.blockID);
        var1.setBlock(var3 + 2, var4 + 4, var5 + 17, DivineRPG.iceikaStoneBricks.blockID);
        var1.setBlock(var3 + 2, var4 + 4, var5 + 18, DivineRPG.iceikaStoneBricks.blockID);
        var1.setBlock(var3 + 2, var4 + 4, var5 + 19, DivineRPG.iceikaStoneBricks.blockID);
        var1.setBlock(var3 + 3, var4 + 0, var5 + 0, DivineRPG.iceikaStoneBricks.blockID);
        var1.setBlock(var3 + 3, var4 + 0, var5 + 1, DivineRPG.iceikaMossyCobble.blockID);
        var1.setBlock(var3 + 3, var4 + 0, var5 + 2, DivineRPG.iceikaMossyCobble.blockID);
        var1.setBlock(var3 + 3, var4 + 0, var5 + 3, DivineRPG.iceikaMossyCobble.blockID);
        var1.setBlock(var3 + 3, var4 + 0, var5 + 4, DivineRPG.iceikaMossyCobble.blockID);
        var1.setBlock(var3 + 3, var4 + 0, var5 + 5, DivineRPG.iceikaMossyCobble.blockID);
        var1.setBlock(var3 + 3, var4 + 0, var5 + 6, DivineRPG.iceikaMossyCobble.blockID);
        var1.setBlock(var3 + 3, var4 + 0, var5 + 7, DivineRPG.iceikaStoneBricks.blockID);
        var1.setBlock(var3 + 3, var4 + 0, var5 + 13, DivineRPG.iceikaStoneBricks.blockID);
        var1.setBlock(var3 + 3, var4 + 0, var5 + 14, DivineRPG.iceikaMossyCobble.blockID);
        var1.setBlock(var3 + 3, var4 + 0, var5 + 15, DivineRPG.iceikaMossyCobble.blockID);
        var1.setBlock(var3 + 3, var4 + 0, var5 + 16, DivineRPG.iceikaMossyCobble.blockID);
        var1.setBlock(var3 + 3, var4 + 0, var5 + 17, DivineRPG.iceikaMossyCobble.blockID);
        var1.setBlock(var3 + 3, var4 + 0, var5 + 18, DivineRPG.iceikaMossyCobble.blockID);
        var1.setBlock(var3 + 3, var4 + 0, var5 + 19, DivineRPG.iceikaMossyCobble.blockID);
        var1.setBlock(var3 + 3, var4 + 0, var5 + 20, DivineRPG.iceikaStoneBricks.blockID);
        var1.setBlock(var3 + 3, var4 + 0, var5 + 21, DivineRPG.iceikaStoneBricks.blockID);
        var1.setBlock(var3 + 3, var4 + 0, var5 + 22, DivineRPG.iceikaStoneBricks.blockID);
        var1.setBlock(var3 + 3, var4 + 0, var5 + 23, DivineRPG.iceikaStoneBricks.blockID);
        var1.setBlock(var3 + 3, var4 + 0, var5 + 24, DivineRPG.iceikaStoneBricks.blockID);
        var1.setBlock(var3 + 3, var4 + 0, var5 + 25, DivineRPG.iceikaStoneBricks.blockID);
        var1.setBlock(var3 + 3, var4 + 1, var5 + 0, DivineRPG.iceikaStoneBricks.blockID);
        var1.setBlock(var3 + 3, var4 + 1, var5 + 1, 0);
        var1.setBlock(var3 + 3, var4 + 1, var5 + 2, 0);
        var1.setBlock(var3 + 3, var4 + 1, var5 + 3, 0);
        var1.setBlock(var3 + 3, var4 + 1, var5 + 4, 0);
        var1.setBlock(var3 + 3, var4 + 1, var5 + 5, 0);
        var1.setBlock(var3 + 3, var4 + 1, var5 + 6, 0);
        var1.setBlock(var3 + 3, var4 + 1, var5 + 7, DivineRPG.iceikaStoneBricks.blockID);
        var1.setBlock(var3 + 3, var4 + 1, var5 + 13, DivineRPG.iceikaStoneBricks.blockID);
        var1.setBlock(var3 + 3, var4 + 1, var5 + 14, 0);
        var1.setBlock(var3 + 3, var4 + 1, var5 + 15, 0);
        var1.setBlock(var3 + 3, var4 + 1, var5 + 16, 0);
        var1.setBlock(var3 + 3, var4 + 1, var5 + 17, 0);
        var1.setBlock(var3 + 3, var4 + 1, var5 + 18, 0);
        var1.setBlock(var3 + 3, var4 + 1, var5 + 19, 0);
        var1.setBlock(var3 + 3, var4 + 1, var5 + 20, DivineRPG.iceikaStoneBricks.blockID);
        var1.setBlock(var3 + 3, var4 + 1, var5 + 21, DivineRPG.iceikaStoneBricks.blockID);
        var1.setBlock(var3 + 3, var4 + 1, var5 + 22, DivineRPG.iceikaStoneBricks.blockID);
        var1.setBlock(var3 + 3, var4 + 1, var5 + 23, DivineRPG.iceikaStoneBricks.blockID);
        var1.setBlock(var3 + 3, var4 + 1, var5 + 24, DivineRPG.iceikaStoneBricks.blockID);
        var1.setBlock(var3 + 3, var4 + 1, var5 + 25, DivineRPG.iceikaStoneBricks.blockID);
        var1.setBlock(var3 + 3, var4 + 2, var5 + 0, DivineRPG.iceikaStoneBricks.blockID);
        var1.setBlock(var3 + 3, var4 + 2, var5 + 1, 0);
        var1.setBlock(var3 + 3, var4 + 2, var5 + 2, 0);
        var1.setBlock(var3 + 3, var4 + 2, var5 + 3, 0);
        var1.setBlock(var3 + 3, var4 + 2, var5 + 4, 0);
        var1.setBlock(var3 + 3, var4 + 2, var5 + 5, 0);
        var1.setBlock(var3 + 3, var4 + 2, var5 + 6, 0);
        var1.setBlock(var3 + 3, var4 + 2, var5 + 7, DivineRPG.iceikaStoneBricks.blockID);
        var1.setBlock(var3 + 3, var4 + 2, var5 + 13, DivineRPG.iceikaStoneBricks.blockID);
        var1.setBlock(var3 + 3, var4 + 2, var5 + 14, 0);
        var1.setBlock(var3 + 3, var4 + 2, var5 + 15, 0);
        var1.setBlock(var3 + 3, var4 + 2, var5 + 16, 0);
        var1.setBlock(var3 + 3, var4 + 2, var5 + 17, 0);
        var1.setBlock(var3 + 3, var4 + 2, var5 + 18, 0);
        var1.setBlock(var3 + 3, var4 + 2, var5 + 19, 0);
        var1.setBlock(var3 + 3, var4 + 2, var5 + 20, DivineRPG.iceikaStoneBricks.blockID);
        var1.setBlock(var3 + 3, var4 + 2, var5 + 21, DivineRPG.iceikaStoneBricks.blockID);
        var1.setBlock(var3 + 3, var4 + 2, var5 + 22, DivineRPG.iceikaStoneBricks.blockID);
        var1.setBlock(var3 + 3, var4 + 2, var5 + 23, DivineRPG.iceikaStoneBricks.blockID);
        var1.setBlock(var3 + 3, var4 + 2, var5 + 24, DivineRPG.iceikaStoneBricks.blockID);
        var1.setBlock(var3 + 3, var4 + 2, var5 + 25, DivineRPG.iceikaStoneBricks.blockID);
        var1.setBlock(var3 + 3, var4 + 3, var5 + 0, DivineRPG.iceikaStoneBricks.blockID);
        var1.setBlock(var3 + 3, var4 + 3, var5 + 1, 0);
        var1.setBlock(var3 + 3, var4 + 3, var5 + 2, 0);
        var1.setBlock(var3 + 3, var4 + 3, var5 + 3, 0);
        var1.setBlock(var3 + 3, var4 + 3, var5 + 4, 0);
        var1.setBlock(var3 + 3, var4 + 3, var5 + 5, 0);
        var1.setBlock(var3 + 3, var4 + 3, var5 + 6, 0);
        var1.setBlock(var3 + 3, var4 + 3, var5 + 7, DivineRPG.iceikaStoneBricks.blockID);
        var1.setBlock(var3 + 3, var4 + 3, var5 + 13, DivineRPG.iceikaStoneBricks.blockID);
        var1.setBlock(var3 + 3, var4 + 3, var5 + 14, 0);
        var1.setBlock(var3 + 3, var4 + 3, var5 + 15, 0);
        var1.setBlock(var3 + 3, var4 + 3, var5 + 16, 0);
        var1.setBlock(var3 + 3, var4 + 3, var5 + 17, 0);
        var1.setBlock(var3 + 3, var4 + 3, var5 + 18, 0);
        var1.setBlock(var3 + 3, var4 + 3, var5 + 19, 0);
        var1.setBlock(var3 + 3, var4 + 3, var5 + 20, DivineRPG.iceikaStoneBricks.blockID);
        var1.setBlock(var3 + 3, var4 + 3, var5 + 21, DivineRPG.iceikaStoneBricks.blockID);
        var1.setBlock(var3 + 3, var4 + 3, var5 + 22, DivineRPG.iceikaStoneBricks.blockID);
        var1.setBlock(var3 + 3, var4 + 3, var5 + 23, DivineRPG.iceikaStoneBricks.blockID);
        var1.setBlock(var3 + 3, var4 + 3, var5 + 24, DivineRPG.iceikaStoneBricks.blockID);
        var1.setBlock(var3 + 3, var4 + 3, var5 + 25, DivineRPG.iceikaStoneBricks.blockID);
        var1.setBlock(var3 + 3, var4 + 4, var5 + 1, DivineRPG.iceikaStoneBricks.blockID);
        var1.setBlock(var3 + 3, var4 + 4, var5 + 2, DivineRPG.iceikaStoneBricks.blockID);
        var1.setBlock(var3 + 3, var4 + 4, var5 + 3, DivineRPG.iceikaStoneBricks.blockID);
        var1.setBlock(var3 + 3, var4 + 4, var5 + 4, DivineRPG.iceikaStoneBricks.blockID);
        var1.setBlock(var3 + 3, var4 + 4, var5 + 5, DivineRPG.iceikaStoneBricks.blockID);
        var1.setBlock(var3 + 3, var4 + 4, var5 + 6, DivineRPG.iceikaStoneBricks.blockID);
        var1.setBlock(var3 + 3, var4 + 4, var5 + 14, DivineRPG.iceikaStoneBricks.blockID);
        var1.setBlock(var3 + 3, var4 + 4, var5 + 15, DivineRPG.iceikaStoneBricks.blockID);
        var1.setBlock(var3 + 3, var4 + 4, var5 + 16, DivineRPG.iceikaStoneBricks.blockID);
        var1.setBlock(var3 + 3, var4 + 4, var5 + 17, DivineRPG.iceikaStoneBricks.blockID);
        var1.setBlock(var3 + 3, var4 + 4, var5 + 18, DivineRPG.iceikaStoneBricks.blockID);
        var1.setBlock(var3 + 3, var4 + 4, var5 + 19, DivineRPG.iceikaStoneBricks.blockID);
        var1.setBlock(var3 + 4, var4 + 0, var5 + 0, DivineRPG.iceikaStoneBricks.blockID);
        var1.setBlock(var3 + 4, var4 + 0, var5 + 1, DivineRPG.iceikaMossyCobble.blockID);
        var1.setBlock(var3 + 4, var4 + 0, var5 + 2, DivineRPG.iceikaMossyCobble.blockID);
        var1.setBlock(var3 + 4, var4 + 0, var5 + 3, DivineRPG.iceikaMossyCobble.blockID);
        var1.setBlock(var3 + 4, var4 + 0, var5 + 4, DivineRPG.iceikaMossyCobble.blockID);
        var1.setBlock(var3 + 4, var4 + 0, var5 + 5, DivineRPG.iceikaMossyCobble.blockID);
        var1.setBlock(var3 + 4, var4 + 0, var5 + 6, DivineRPG.iceikaMossyCobble.blockID);
        var1.setBlock(var3 + 4, var4 + 0, var5 + 7, DivineRPG.iceikaStoneBricks.blockID);
        var1.setBlock(var3 + 4, var4 + 0, var5 + 13, DivineRPG.iceikaStoneBricks.blockID);
        var1.setBlock(var3 + 4, var4 + 0, var5 + 14, DivineRPG.iceikaMossyCobble.blockID);
        var1.setBlock(var3 + 4, var4 + 0, var5 + 15, DivineRPG.iceikaMossyCobble.blockID);
        var1.setBlock(var3 + 4, var4 + 0, var5 + 16, DivineRPG.iceikaMossyCobble.blockID);
        var1.setBlock(var3 + 4, var4 + 0, var5 + 17, DivineRPG.iceikaMossyCobble.blockID);
        var1.setBlock(var3 + 4, var4 + 0, var5 + 18, DivineRPG.iceikaMossyCobble.blockID);
        var1.setBlock(var3 + 4, var4 + 0, var5 + 19, DivineRPG.iceikaMossyCobble.blockID);
        var1.setBlock(var3 + 4, var4 + 0, var5 + 20, DivineRPG.iceikaMossyCobble.blockID);
        var1.setBlock(var3 + 4, var4 + 0, var5 + 21, DivineRPG.iceikaMossyCobble.blockID);
        var1.setBlock(var3 + 4, var4 + 0, var5 + 22, DivineRPG.iceikaMossyCobble.blockID);
        var1.setBlock(var3 + 4, var4 + 0, var5 + 23, DivineRPG.iceikaMossyCobble.blockID);
        var1.setBlock(var3 + 4, var4 + 0, var5 + 24, DivineRPG.iceikaMossyCobble.blockID);
        var1.setBlock(var3 + 4, var4 + 0, var5 + 25, DivineRPG.iceikaMossyCobble.blockID);
        var1.setBlock(var3 + 4, var4 + 1, var5 + 0, DivineRPG.iceikaStoneBricks.blockID);
        var1.setBlock(var3 + 4, var4 + 1, var5 + 1, 0);
        var1.setBlock(var3 + 4, var4 + 1, var5 + 2, DivineRPG.iceikaSpawnerCage2.blockID);
        var1.setBlock(var3 + 4, var4 + 1, var5 + 3, 0);
        var1.setBlock(var3 + 4, var4 + 1, var5 + 4, 0);
        var1.setBlock(var3 + 4, var4 + 1, var5 + 5, DivineRPG.iceikaSpawnerCage2.blockID);
        var1.setBlock(var3 + 4, var4 + 1, var5 + 6, 0);
        var1.setBlock(var3 + 4, var4 + 1, var5 + 7, DivineRPG.iceikaStoneBricks.blockID);
        var1.setBlock(var3 + 4, var4 + 1, var5 + 13, DivineRPG.iceikaStoneBricks.blockID);
        var1.setBlock(var3 + 4, var4 + 1, var5 + 14, 0);
        var1.setBlock(var3 + 4, var4 + 1, var5 + 15, 0);
        var1.setBlock(var3 + 4, var4 + 1, var5 + 16, DivineRPG.iceikaSpawnerCage2.blockID);
        var1.setBlock(var3 + 4, var4 + 1, var5 + 17, 0);
        var1.setBlock(var3 + 4, var4 + 1, var5 + 18, 0);
        var1.setBlock(var3 + 4, var4 + 1, var5 + 19, 0);
        var1.setBlock(var3 + 4, var4 + 1, var5 + 20, 0);
        var1.setBlock(var3 + 4, var4 + 1, var5 + 21, 0);
        var1.setBlock(var3 + 4, var4 + 1, var5 + 22, 0);
        var1.setBlock(var3 + 4, var4 + 1, var5 + 23, 0);
        var1.setBlock(var3 + 4, var4 + 1, var5 + 24, 0);
        var1.setBlock(var3 + 4, var4 + 2, var5 + 0, DivineRPG.iceikaStoneBricks.blockID);
        var1.setBlock(var3 + 4, var4 + 2, var5 + 1, 0);
        var1.setBlock(var3 + 4, var4 + 2, var5 + 2, 0);
        var1.setBlock(var3 + 4, var4 + 2, var5 + 3, 0);
        var1.setBlock(var3 + 4, var4 + 2, var5 + 4, 0);
        var1.setBlock(var3 + 4, var4 + 2, var5 + 5, 0);
        var1.setBlock(var3 + 4, var4 + 2, var5 + 6, 0);
        var1.setBlock(var3 + 4, var4 + 2, var5 + 7, DivineRPG.iceikaStoneBricks.blockID);
        var1.setBlock(var3 + 4, var4 + 2, var5 + 13, DivineRPG.iceikaStoneBricks.blockID);
        var1.setBlock(var3 + 4, var4 + 2, var5 + 14, 0);
        var1.setBlock(var3 + 4, var4 + 2, var5 + 15, 0);
        var1.setBlock(var3 + 4, var4 + 2, var5 + 16, 0);
        var1.setBlock(var3 + 4, var4 + 2, var5 + 17, 0);
        var1.setBlock(var3 + 4, var4 + 2, var5 + 18, 0);
        var1.setBlock(var3 + 4, var4 + 2, var5 + 19, 0);
        var1.setBlock(var3 + 4, var4 + 2, var5 + 20, 0);
        var1.setBlock(var3 + 4, var4 + 2, var5 + 21, 0);
        var1.setBlock(var3 + 4, var4 + 2, var5 + 22, 0);
        var1.setBlock(var3 + 4, var4 + 2, var5 + 23, 0);
        var1.setBlock(var3 + 4, var4 + 2, var5 + 24, 0);
        var1.setBlock(var3 + 4, var4 + 3, var5 + 0, DivineRPG.iceikaStoneBricks.blockID);
        var1.setBlock(var3 + 4, var4 + 3, var5 + 1, 0);
        var1.setBlock(var3 + 4, var4 + 3, var5 + 2, 0);
        var1.setBlock(var3 + 4, var4 + 3, var5 + 3, 0);
        var1.setBlock(var3 + 4, var4 + 3, var5 + 4, 0);
        var1.setBlock(var3 + 4, var4 + 3, var5 + 5, 0);
        var1.setBlock(var3 + 4, var4 + 3, var5 + 6, 0);
        var1.setBlock(var3 + 4, var4 + 3, var5 + 7, DivineRPG.iceikaStoneBricks.blockID);
        var1.setBlock(var3 + 4, var4 + 3, var5 + 13, DivineRPG.iceikaStoneBricks.blockID);
        var1.setBlock(var3 + 4, var4 + 3, var5 + 14, 0);
        var1.setBlock(var3 + 4, var4 + 3, var5 + 15, 0);
        var1.setBlock(var3 + 4, var4 + 3, var5 + 16, 0);
        var1.setBlock(var3 + 4, var4 + 3, var5 + 17, 0);
        var1.setBlock(var3 + 4, var4 + 3, var5 + 18, 0);
        var1.setBlock(var3 + 4, var4 + 3, var5 + 19, 0);
        var1.setBlock(var3 + 4, var4 + 3, var5 + 20, 0);
        var1.setBlock(var3 + 4, var4 + 3, var5 + 21, 0);
        var1.setBlock(var3 + 4, var4 + 3, var5 + 22, 0);
        var1.setBlock(var3 + 4, var4 + 3, var5 + 23, 0);
        var1.setBlock(var3 + 4, var4 + 3, var5 + 24, 0);
        var1.setBlock(var3 + 4, var4 + 4, var5 + 1, DivineRPG.iceikaStoneBricks.blockID);
        var1.setBlock(var3 + 4, var4 + 4, var5 + 2, DivineRPG.iceikaStoneBricks.blockID);
        var1.setBlock(var3 + 4, var4 + 4, var5 + 3, DivineRPG.iceikaStoneBricks.blockID);
        var1.setBlock(var3 + 4, var4 + 4, var5 + 4, DivineRPG.iceikaStoneBricks.blockID);
        var1.setBlock(var3 + 4, var4 + 4, var5 + 5, DivineRPG.iceikaStoneBricks.blockID);
        var1.setBlock(var3 + 4, var4 + 4, var5 + 6, DivineRPG.iceikaStoneBricks.blockID);
        var1.setBlock(var3 + 4, var4 + 4, var5 + 14, DivineRPG.iceikaStoneBricks.blockID);
        var1.setBlock(var3 + 4, var4 + 4, var5 + 15, DivineRPG.iceikaStoneBricks.blockID);
        var1.setBlock(var3 + 4, var4 + 4, var5 + 16, DivineRPG.iceikaStoneBricks.blockID);
        var1.setBlock(var3 + 4, var4 + 4, var5 + 17, DivineRPG.iceikaStoneBricks.blockID);
        var1.setBlock(var3 + 4, var4 + 4, var5 + 18, DivineRPG.iceikaStoneBricks.blockID);
        var1.setBlock(var3 + 4, var4 + 4, var5 + 19, DivineRPG.iceikaStoneBricks.blockID);
        var1.setBlock(var3 + 4, var4 + 4, var5 + 20, DivineRPG.iceikaStoneBricks.blockID);
        var1.setBlock(var3 + 4, var4 + 4, var5 + 21, DivineRPG.iceikaStoneBricks.blockID);
        var1.setBlock(var3 + 4, var4 + 4, var5 + 22, DivineRPG.iceikaStoneBricks.blockID);
        var1.setBlock(var3 + 4, var4 + 4, var5 + 23, DivineRPG.iceikaStoneBricks.blockID);
        var1.setBlock(var3 + 4, var4 + 4, var5 + 24, DivineRPG.iceikaStoneBricks.blockID);
        var1.setBlock(var3 + 4, var4 + 4, var5 + 25, DivineRPG.iceikaStoneBricks.blockID);
        var1.setBlock(var3 + 5, var4 + 0, var5 + 0, DivineRPG.iceikaStoneBricks.blockID);
        var1.setBlock(var3 + 5, var4 + 0, var5 + 1, DivineRPG.iceikaMossyCobble.blockID);
        var1.setBlock(var3 + 5, var4 + 0, var5 + 2, DivineRPG.iceikaMossyCobble.blockID);
        var1.setBlock(var3 + 5, var4 + 0, var5 + 3, DivineRPG.iceikaMossyCobble.blockID);
        var1.setBlock(var3 + 5, var4 + 0, var5 + 4, DivineRPG.iceikaMossyCobble.blockID);
        var1.setBlock(var3 + 5, var4 + 0, var5 + 5, DivineRPG.iceikaMossyCobble.blockID);
        var1.setBlock(var3 + 5, var4 + 0, var5 + 6, DivineRPG.iceikaMossyCobble.blockID);
        var1.setBlock(var3 + 5, var4 + 0, var5 + 7, DivineRPG.iceikaStoneBricks.blockID);
        var1.setBlock(var3 + 5, var4 + 0, var5 + 9, DivineRPG.iceikaStoneBricks.blockID);
        var1.setBlock(var3 + 5, var4 + 0, var5 + 10, DivineRPG.iceikaStoneBricks.blockID);
        var1.setBlock(var3 + 5, var4 + 0, var5 + 11, DivineRPG.iceikaStoneBricks.blockID);
        var1.setBlock(var3 + 5, var4 + 0, var5 + 12, DivineRPG.iceikaStoneBricks.blockID);
        var1.setBlock(var3 + 5, var4 + 0, var5 + 13, DivineRPG.iceikaStoneBricks.blockID);
        var1.setBlock(var3 + 5, var4 + 0, var5 + 14, DivineRPG.iceikaMossyCobble.blockID);
        var1.setBlock(var3 + 5, var4 + 0, var5 + 15, DivineRPG.iceikaMossyCobble.blockID);
        var1.setBlock(var3 + 5, var4 + 0, var5 + 16, DivineRPG.iceikaMossyCobble.blockID);
        var1.setBlock(var3 + 5, var4 + 0, var5 + 17, DivineRPG.iceikaMossyCobble.blockID);
        var1.setBlock(var3 + 5, var4 + 0, var5 + 18, DivineRPG.iceikaMossyCobble.blockID);
        var1.setBlock(var3 + 5, var4 + 0, var5 + 19, DivineRPG.iceikaMossyCobble.blockID);
        var1.setBlock(var3 + 5, var4 + 0, var5 + 20, DivineRPG.iceikaMossyCobble.blockID);
        var1.setBlock(var3 + 5, var4 + 0, var5 + 21, DivineRPG.iceikaMossyCobble.blockID);
        var1.setBlock(var3 + 5, var4 + 0, var5 + 22, DivineRPG.iceikaMossyCobble.blockID);
        var1.setBlock(var3 + 5, var4 + 0, var5 + 23, DivineRPG.iceikaMossyCobble.blockID);
        var1.setBlock(var3 + 5, var4 + 0, var5 + 24, DivineRPG.iceikaMossyCobble.blockID);
        var1.setBlock(var3 + 5, var4 + 0, var5 + 25, DivineRPG.iceikaMossyCobble.blockID);
        var1.setBlock(var3 + 5, var4 + 1, var5 + 0, DivineRPG.iceikaStoneBricks.blockID);
        var1.setBlock(var3 + 5, var4 + 1, var5 + 1, 0);
        var1.setBlock(var3 + 5, var4 + 1, var5 + 2, 0);
        var1.setBlock(var3 + 5, var4 + 1, var5 + 3, 0);
        var1.setBlock(var3 + 5, var4 + 1, var5 + 4, 0);
        var1.setBlock(var3 + 5, var4 + 1, var5 + 5, 0);
        var1.setBlock(var3 + 5, var4 + 1, var5 + 6, 0);
        var1.setBlock(var3 + 5, var4 + 1, var5 + 7, DivineRPG.iceikaStoneBricks.blockID);
        var1.setBlock(var3 + 5, var4 + 1, var5 + 9, DivineRPG.iceikaStoneBricks.blockID);
        var1.setBlock(var3 + 5, var4 + 1, var5 + 10, DivineRPG.iceikaStoneBricks.blockID);
        var1.setBlock(var3 + 5, var4 + 1, var5 + 11, DivineRPG.iceikaStoneBricks.blockID);
        var1.setBlock(var3 + 5, var4 + 1, var5 + 12, DivineRPG.iceikaStoneBricks.blockID);
        var1.setBlock(var3 + 5, var4 + 1, var5 + 13, DivineRPG.iceikaStoneBricks.blockID);
        var1.setBlock(var3 + 5, var4 + 1, var5 + 14, 0);
        var1.setBlock(var3 + 5, var4 + 1, var5 + 15, 0);
        var1.setBlock(var3 + 5, var4 + 1, var5 + 16, 0);
        var1.setBlock(var3 + 5, var4 + 1, var5 + 17, 0);
        var1.setBlock(var3 + 5, var4 + 1, var5 + 18, 0);
        var1.setBlock(var3 + 5, var4 + 1, var5 + 19, 0);
        var1.setBlock(var3 + 5, var4 + 1, var5 + 20, 0);
        var1.setBlock(var3 + 5, var4 + 1, var5 + 21, 0);
        var1.setBlock(var3 + 5, var4 + 1, var5 + 22, 0);
        var1.setBlock(var3 + 5, var4 + 1, var5 + 23, 0);
        var1.setBlock(var3 + 5, var4 + 1, var5 + 24, 0);
        var1.setBlock(var3 + 5, var4 + 2, var5 + 0, DivineRPG.iceikaStoneBricks.blockID);
        var1.setBlock(var3 + 5, var4 + 2, var5 + 1, 0);
        var1.setBlock(var3 + 5, var4 + 2, var5 + 2, 0);
        var1.setBlock(var3 + 5, var4 + 2, var5 + 3, 0);
        var1.setBlock(var3 + 5, var4 + 2, var5 + 4, 0);
        var1.setBlock(var3 + 5, var4 + 2, var5 + 5, 0);
        var1.setBlock(var3 + 5, var4 + 2, var5 + 6, 0);
        var1.setBlock(var3 + 5, var4 + 2, var5 + 7, DivineRPG.iceikaStoneBricks.blockID);
        var1.setBlock(var3 + 5, var4 + 2, var5 + 9, DivineRPG.iceikaStoneBricks.blockID);
        var1.setBlock(var3 + 5, var4 + 2, var5 + 10, DivineRPG.iceikaStoneBricks.blockID);
        var1.setBlock(var3 + 5, var4 + 2, var5 + 11, DivineRPG.iceikaStoneBricks.blockID);
        var1.setBlock(var3 + 5, var4 + 2, var5 + 12, DivineRPG.iceikaStoneBricks.blockID);
        var1.setBlock(var3 + 5, var4 + 2, var5 + 13, DivineRPG.iceikaStoneBricks.blockID);
        var1.setBlock(var3 + 5, var4 + 2, var5 + 14, 0);
        var1.setBlock(var3 + 5, var4 + 2, var5 + 15, 0);
        var1.setBlock(var3 + 5, var4 + 2, var5 + 16, 0);
        var1.setBlock(var3 + 5, var4 + 2, var5 + 17, 0);
        var1.setBlock(var3 + 5, var4 + 2, var5 + 18, 0);
        var1.setBlock(var3 + 5, var4 + 2, var5 + 19, 0);
        var1.setBlock(var3 + 5, var4 + 2, var5 + 20, 0);
        var1.setBlock(var3 + 5, var4 + 2, var5 + 21, 0);
        var1.setBlock(var3 + 5, var4 + 2, var5 + 22, 0);
        var1.setBlock(var3 + 5, var4 + 2, var5 + 23, 0);
        var1.setBlock(var3 + 5, var4 + 2, var5 + 24, 0);
        var1.setBlock(var3 + 5, var4 + 3, var5 + 0, DivineRPG.iceikaStoneBricks.blockID);
        var1.setBlock(var3 + 5, var4 + 3, var5 + 1, 0);
        var1.setBlock(var3 + 5, var4 + 3, var5 + 2, 0);
        var1.setBlock(var3 + 5, var4 + 3, var5 + 3, 0);
        var1.setBlock(var3 + 5, var4 + 3, var5 + 4, 0);
        var1.setBlock(var3 + 5, var4 + 3, var5 + 5, 0);
        var1.setBlock(var3 + 5, var4 + 3, var5 + 6, 0);
        var1.setBlock(var3 + 5, var4 + 3, var5 + 7, DivineRPG.iceikaStoneBricks.blockID);
        var1.setBlock(var3 + 5, var4 + 3, var5 + 9, DivineRPG.iceikaStoneBricks.blockID);
        var1.setBlock(var3 + 5, var4 + 3, var5 + 10, DivineRPG.iceikaStoneBricks.blockID);
        var1.setBlock(var3 + 5, var4 + 3, var5 + 11, DivineRPG.iceikaStoneBricks.blockID);
        var1.setBlock(var3 + 5, var4 + 3, var5 + 12, DivineRPG.iceikaStoneBricks.blockID);
        var1.setBlock(var3 + 5, var4 + 3, var5 + 13, DivineRPG.iceikaStoneBricks.blockID);
        var1.setBlock(var3 + 5, var4 + 3, var5 + 14, 0);
        var1.setBlock(var3 + 5, var4 + 3, var5 + 15, 0);
        var1.setBlock(var3 + 5, var4 + 3, var5 + 16, 0);
        var1.setBlock(var3 + 5, var4 + 3, var5 + 17, 0);
        var1.setBlock(var3 + 5, var4 + 3, var5 + 18, 0);
        var1.setBlock(var3 + 5, var4 + 3, var5 + 19, 0);
        var1.setBlock(var3 + 5, var4 + 3, var5 + 20, 0);
        var1.setBlock(var3 + 5, var4 + 3, var5 + 21, 0);
        var1.setBlock(var3 + 5, var4 + 3, var5 + 22, 0);
        var1.setBlock(var3 + 5, var4 + 3, var5 + 23, 0);
        var1.setBlock(var3 + 5, var4 + 3, var5 + 24, 0);
        var1.setBlock(var3 + 5, var4 + 4, var5 + 1, DivineRPG.iceikaStoneBricks.blockID);
        var1.setBlock(var3 + 5, var4 + 4, var5 + 2, DivineRPG.iceikaStoneBricks.blockID);
        var1.setBlock(var3 + 5, var4 + 4, var5 + 3, DivineRPG.iceikaStoneBricks.blockID);
        var1.setBlock(var3 + 5, var4 + 4, var5 + 4, DivineRPG.iceikaStoneBricks.blockID);
        var1.setBlock(var3 + 5, var4 + 4, var5 + 5, DivineRPG.iceikaStoneBricks.blockID);
        var1.setBlock(var3 + 5, var4 + 4, var5 + 6, DivineRPG.iceikaStoneBricks.blockID);
        var1.setBlock(var3 + 5, var4 + 4, var5 + 14, DivineRPG.iceikaStoneBricks.blockID);
        var1.setBlock(var3 + 5, var4 + 4, var5 + 15, DivineRPG.iceikaStoneBricks.blockID);
        var1.setBlock(var3 + 5, var4 + 4, var5 + 16, DivineRPG.iceikaStoneBricks.blockID);
        var1.setBlock(var3 + 5, var4 + 4, var5 + 17, DivineRPG.iceikaStoneBricks.blockID);
        var1.setBlock(var3 + 5, var4 + 4, var5 + 18, DivineRPG.iceikaStoneBricks.blockID);
        var1.setBlock(var3 + 5, var4 + 4, var5 + 19, DivineRPG.iceikaStoneBricks.blockID);
        var1.setBlock(var3 + 5, var4 + 4, var5 + 20, DivineRPG.iceikaStoneBricks.blockID);
        var1.setBlock(var3 + 5, var4 + 4, var5 + 21, DivineRPG.iceikaStoneBricks.blockID);
        var1.setBlock(var3 + 5, var4 + 4, var5 + 22, DivineRPG.iceikaStoneBricks.blockID);
        var1.setBlock(var3 + 5, var4 + 4, var5 + 23, DivineRPG.iceikaStoneBricks.blockID);
        var1.setBlock(var3 + 5, var4 + 4, var5 + 24, DivineRPG.iceikaStoneBricks.blockID);
        var1.setBlock(var3 + 5, var4 + 4, var5 + 25, DivineRPG.iceikaStoneBricks.blockID);
        var1.setBlock(var3 + 6, var4 + 0, var5 + 0, DivineRPG.iceikaStoneBricks.blockID);
        var1.setBlock(var3 + 6, var4 + 0, var5 + 1, DivineRPG.iceikaMossyCobble.blockID);
        var1.setBlock(var3 + 6, var4 + 0, var5 + 2, DivineRPG.iceikaMossyCobble.blockID);
        var1.setBlock(var3 + 6, var4 + 0, var5 + 3, DivineRPG.iceikaMossyCobble.blockID);
        var1.setBlock(var3 + 6, var4 + 0, var5 + 4, DivineRPG.iceikaMossyCobble.blockID);
        var1.setBlock(var3 + 6, var4 + 0, var5 + 5, DivineRPG.iceikaMossyCobble.blockID);
        var1.setBlock(var3 + 6, var4 + 0, var5 + 6, DivineRPG.iceikaMossyCobble.blockID);
        var1.setBlock(var3 + 6, var4 + 0, var5 + 7, DivineRPG.iceikaStoneBricks.blockID);
        var1.setBlock(var3 + 6, var4 + 0, var5 + 9, DivineRPG.iceikaStoneBricks.blockID);
        var1.setBlock(var3 + 6, var4 + 0, var5 + 10, DivineRPG.iceikaMossyCobble.blockID);
        var1.setBlock(var3 + 6, var4 + 0, var5 + 11, DivineRPG.iceikaMossyCobble.blockID);
        var1.setBlock(var3 + 6, var4 + 0, var5 + 12, DivineRPG.iceikaMossyCobble.blockID);
        var1.setBlock(var3 + 6, var4 + 0, var5 + 13, DivineRPG.iceikaMossyCobble.blockID);
        var1.setBlock(var3 + 6, var4 + 0, var5 + 14, DivineRPG.iceikaMossyCobble.blockID);
        var1.setBlock(var3 + 6, var4 + 0, var5 + 15, DivineRPG.iceikaMossyCobble.blockID);
        var1.setBlock(var3 + 6, var4 + 0, var5 + 16, DivineRPG.iceikaMossyCobble.blockID);
        var1.setBlock(var3 + 6, var4 + 0, var5 + 17, DivineRPG.iceikaMossyCobble.blockID);
        var1.setBlock(var3 + 6, var4 + 0, var5 + 18, DivineRPG.iceikaMossyCobble.blockID);
        var1.setBlock(var3 + 6, var4 + 0, var5 + 19, DivineRPG.iceikaMossyCobble.blockID);
        var1.setBlock(var3 + 6, var4 + 0, var5 + 20, DivineRPG.iceikaStoneBricks.blockID);
        var1.setBlock(var3 + 6, var4 + 0, var5 + 21, DivineRPG.iceikaStoneBricks.blockID);
        var1.setBlock(var3 + 6, var4 + 0, var5 + 22, DivineRPG.iceikaStoneBricks.blockID);
        var1.setBlock(var3 + 6, var4 + 0, var5 + 23, DivineRPG.iceikaStoneBricks.blockID);
        var1.setBlock(var3 + 6, var4 + 0, var5 + 24, DivineRPG.iceikaStoneBricks.blockID);
        var1.setBlock(var3 + 6, var4 + 0, var5 + 25, DivineRPG.iceikaStoneBricks.blockID);
        var1.setBlock(var3 + 6, var4 + 1, var5 + 0, DivineRPG.iceikaStoneBricks.blockID);
        var1.setBlock(var3 + 6, var4 + 1, var5 + 1, 0);
        var1.setBlock(var3 + 6, var4 + 1, var5 + 2, 0);
        var1.setBlock(var3 + 6, var4 + 1, var5 + 3, 0);
        var1.setBlock(var3 + 6, var4 + 1, var5 + 4, 0);
        var1.setBlock(var3 + 6, var4 + 1, var5 + 5, 0);
        var1.setBlock(var3 + 6, var4 + 1, var5 + 6, 0);
        var1.setBlock(var3 + 6, var4 + 1, var5 + 7, DivineRPG.iceikaStoneBricks.blockID);
        var1.setBlock(var3 + 6, var4 + 1, var5 + 9, DivineRPG.iceikaStoneBricks.blockID);
        var1.setBlock(var3 + 6, var4 + 1, var5 + 10, 0);
        var1.setBlock(var3 + 6, var4 + 1, var5 + 11, 0);
        var1.setBlock(var3 + 6, var4 + 1, var5 + 12, 0);
        var1.setBlock(var3 + 6, var4 + 1, var5 + 13, 0);
        var1.setBlock(var3 + 6, var4 + 1, var5 + 14, 0);
        var1.setBlock(var3 + 6, var4 + 1, var5 + 15, 0);
        var1.setBlock(var3 + 6, var4 + 1, var5 + 16, 0);
        var1.setBlock(var3 + 6, var4 + 1, var5 + 17, 0);
        var1.setBlock(var3 + 6, var4 + 1, var5 + 18, 0);
        var1.setBlock(var3 + 6, var4 + 1, var5 + 19, 0);
        var1.setBlock(var3 + 6, var4 + 1, var5 + 20, DivineRPG.iceikaStoneBricks.blockID);
        var1.setBlock(var3 + 6, var4 + 1, var5 + 21, DivineRPG.iceikaStoneBricks.blockID);
        var1.setBlock(var3 + 6, var4 + 1, var5 + 22, DivineRPG.iceikaStoneBricks.blockID);
        var1.setBlock(var3 + 6, var4 + 1, var5 + 23, DivineRPG.iceikaStoneBricks.blockID);
        var1.setBlock(var3 + 6, var4 + 1, var5 + 24, DivineRPG.iceikaStoneBricks.blockID);
        var1.setBlock(var3 + 6, var4 + 1, var5 + 25, DivineRPG.iceikaStoneBricks.blockID);
        var1.setBlock(var3 + 6, var4 + 2, var5 + 0, DivineRPG.iceikaStoneBricks.blockID);
        var1.setBlock(var3 + 6, var4 + 2, var5 + 1, 0);
        var1.setBlock(var3 + 6, var4 + 2, var5 + 2, 0);
        var1.setBlock(var3 + 6, var4 + 2, var5 + 3, 0);
        var1.setBlock(var3 + 6, var4 + 2, var5 + 4, 0);
        var1.setBlock(var3 + 6, var4 + 2, var5 + 5, 0);
        var1.setBlock(var3 + 6, var4 + 2, var5 + 6, 0);
        var1.setBlock(var3 + 6, var4 + 2, var5 + 7, DivineRPG.iceikaStoneBricks.blockID);
        var1.setBlock(var3 + 6, var4 + 2, var5 + 9, DivineRPG.iceikaStoneBricks.blockID);
        var1.setBlock(var3 + 6, var4 + 2, var5 + 10, 0);
        var1.setBlock(var3 + 6, var4 + 2, var5 + 11, 0);
        var1.setBlock(var3 + 6, var4 + 2, var5 + 12, 0);
        var1.setBlock(var3 + 6, var4 + 2, var5 + 13, 0);
        var1.setBlock(var3 + 6, var4 + 2, var5 + 14, 0);
        var1.setBlock(var3 + 6, var4 + 2, var5 + 15, 0);
        var1.setBlock(var3 + 6, var4 + 2, var5 + 16, 0);
        var1.setBlock(var3 + 6, var4 + 2, var5 + 17, 0);
        var1.setBlock(var3 + 6, var4 + 2, var5 + 18, 0);
        var1.setBlock(var3 + 6, var4 + 2, var5 + 19, 0);
        var1.setBlock(var3 + 6, var4 + 2, var5 + 20, DivineRPG.iceikaStoneBricks.blockID);
        var1.setBlock(var3 + 6, var4 + 2, var5 + 21, DivineRPG.iceikaStoneBricks.blockID);
        var1.setBlock(var3 + 6, var4 + 2, var5 + 22, DivineRPG.iceikaStoneBricks.blockID);
        var1.setBlock(var3 + 6, var4 + 2, var5 + 23, DivineRPG.iceikaStoneBricks.blockID);
        var1.setBlock(var3 + 6, var4 + 2, var5 + 24, DivineRPG.iceikaStoneBricks.blockID);
        var1.setBlock(var3 + 6, var4 + 2, var5 + 25, DivineRPG.iceikaStoneBricks.blockID);
        var1.setBlock(var3 + 6, var4 + 3, var5 + 0, DivineRPG.iceikaStoneBricks.blockID);
        var1.setBlock(var3 + 6, var4 + 3, var5 + 1, 0);
        var1.setBlock(var3 + 6, var4 + 3, var5 + 2, 0);
        var1.setBlock(var3 + 6, var4 + 3, var5 + 3, 0);
        var1.setBlock(var3 + 6, var4 + 3, var5 + 4, 0);
        var1.setBlock(var3 + 6, var4 + 3, var5 + 5, 0);
        var1.setBlock(var3 + 6, var4 + 3, var5 + 6, 0);
        var1.setBlock(var3 + 6, var4 + 3, var5 + 7, DivineRPG.iceikaStoneBricks.blockID);
        var1.setBlock(var3 + 6, var4 + 3, var5 + 9, DivineRPG.iceikaStoneBricks.blockID);
        var1.setBlock(var3 + 6, var4 + 3, var5 + 10, 0);
        var1.setBlock(var3 + 6, var4 + 3, var5 + 11, 0);
        var1.setBlock(var3 + 6, var4 + 3, var5 + 12, 0);
        var1.setBlock(var3 + 6, var4 + 3, var5 + 13, 0);
        var1.setBlock(var3 + 6, var4 + 3, var5 + 14, 0);
        var1.setBlock(var3 + 6, var4 + 3, var5 + 15, 0);
        var1.setBlock(var3 + 6, var4 + 3, var5 + 16, 0);
        var1.setBlock(var3 + 6, var4 + 3, var5 + 17, 0);
        var1.setBlock(var3 + 6, var4 + 3, var5 + 18, 0);
        var1.setBlock(var3 + 6, var4 + 3, var5 + 19, 0);
        var1.setBlock(var3 + 6, var4 + 3, var5 + 20, DivineRPG.iceikaStoneBricks.blockID);
        var1.setBlock(var3 + 6, var4 + 3, var5 + 21, DivineRPG.iceikaStoneBricks.blockID);
        var1.setBlock(var3 + 6, var4 + 3, var5 + 22, DivineRPG.iceikaStoneBricks.blockID);
        var1.setBlock(var3 + 6, var4 + 3, var5 + 23, DivineRPG.iceikaStoneBricks.blockID);
        var1.setBlock(var3 + 6, var4 + 3, var5 + 24, DivineRPG.iceikaStoneBricks.blockID);
        var1.setBlock(var3 + 6, var4 + 3, var5 + 25, DivineRPG.iceikaStoneBricks.blockID);
        var1.setBlock(var3 + 6, var4 + 4, var5 + 1, DivineRPG.iceikaStoneBricks.blockID);
        var1.setBlock(var3 + 6, var4 + 4, var5 + 2, DivineRPG.iceikaStoneBricks.blockID);
        var1.setBlock(var3 + 6, var4 + 4, var5 + 3, DivineRPG.iceikaStoneBricks.blockID);
        var1.setBlock(var3 + 6, var4 + 4, var5 + 4, DivineRPG.iceikaStoneBricks.blockID);
        var1.setBlock(var3 + 6, var4 + 4, var5 + 5, DivineRPG.iceikaStoneBricks.blockID);
        var1.setBlock(var3 + 6, var4 + 4, var5 + 6, DivineRPG.iceikaStoneBricks.blockID);
        var1.setBlock(var3 + 6, var4 + 4, var5 + 10, DivineRPG.iceikaStoneBricks.blockID);
        var1.setBlock(var3 + 6, var4 + 4, var5 + 11, DivineRPG.iceikaStoneBricks.blockID);
        var1.setBlock(var3 + 6, var4 + 4, var5 + 12, DivineRPG.iceikaStoneBricks.blockID);
        var1.setBlock(var3 + 6, var4 + 4, var5 + 13, DivineRPG.iceikaStoneBricks.blockID);
        var1.setBlock(var3 + 6, var4 + 4, var5 + 14, DivineRPG.iceikaStoneBricks.blockID);
        var1.setBlock(var3 + 6, var4 + 4, var5 + 15, DivineRPG.iceikaStoneBricks.blockID);
        var1.setBlock(var3 + 6, var4 + 4, var5 + 16, DivineRPG.iceikaStoneBricks.blockID);
        var1.setBlock(var3 + 6, var4 + 4, var5 + 17, DivineRPG.iceikaStoneBricks.blockID);
        var1.setBlock(var3 + 6, var4 + 4, var5 + 18, DivineRPG.iceikaStoneBricks.blockID);
        var1.setBlock(var3 + 6, var4 + 4, var5 + 19, DivineRPG.iceikaStoneBricks.blockID);
        var1.setBlock(var3 + 7, var4 + 0, var5 + 0, DivineRPG.iceikaStoneBricks.blockID);
        var1.setBlock(var3 + 7, var4 + 0, var5 + 1, DivineRPG.iceikaStoneBricks.blockID);
        var1.setBlock(var3 + 7, var4 + 0, var5 + 2, DivineRPG.iceikaStoneBricks.blockID);
        var1.setBlock(var3 + 7, var4 + 0, var5 + 3, DivineRPG.iceikaMossyCobble.blockID);
        var1.setBlock(var3 + 7, var4 + 0, var5 + 4, DivineRPG.iceikaMossyCobble.blockID);
        var1.setBlock(var3 + 7, var4 + 0, var5 + 5, DivineRPG.iceikaStoneBricks.blockID);
        var1.setBlock(var3 + 7, var4 + 0, var5 + 6, DivineRPG.iceikaStoneBricks.blockID);
        var1.setBlock(var3 + 7, var4 + 0, var5 + 7, DivineRPG.iceikaStoneBricks.blockID);
        var1.setBlock(var3 + 7, var4 + 0, var5 + 9, DivineRPG.iceikaStoneBricks.blockID);
        var1.setBlock(var3 + 7, var4 + 0, var5 + 10, DivineRPG.iceikaMossyCobble.blockID);
        var1.setBlock(var3 + 7, var4 + 0, var5 + 11, DivineRPG.iceikaMossyCobble.blockID);
        var1.setBlock(var3 + 7, var4 + 0, var5 + 12, DivineRPG.iceikaMossyCobble.blockID);
        var1.setBlock(var3 + 7, var4 + 0, var5 + 13, DivineRPG.iceikaMossyCobble.blockID);
        var1.setBlock(var3 + 7, var4 + 0, var5 + 14, DivineRPG.iceikaMossyCobble.blockID);
        var1.setBlock(var3 + 7, var4 + 0, var5 + 15, DivineRPG.iceikaMossyCobble.blockID);
        var1.setBlock(var3 + 7, var4 + 0, var5 + 16, DivineRPG.iceikaMossyCobble.blockID);
        var1.setBlock(var3 + 7, var4 + 0, var5 + 17, DivineRPG.iceikaMossyCobble.blockID);
        var1.setBlock(var3 + 7, var4 + 0, var5 + 18, DivineRPG.iceikaMossyCobble.blockID);
        var1.setBlock(var3 + 7, var4 + 0, var5 + 19, DivineRPG.iceikaMossyCobble.blockID);
        var1.setBlock(var3 + 7, var4 + 0, var5 + 20, DivineRPG.iceikaStoneBricks.blockID);
        var1.setBlock(var3 + 7, var4 + 1, var5 + 0, DivineRPG.iceikaStoneBricks.blockID);
        var1.setBlock(var3 + 7, var4 + 1, var5 + 1, DivineRPG.iceikaStoneBricks.blockID);
        var1.setBlock(var3 + 7, var4 + 1, var5 + 2, DivineRPG.iceikaStoneBricks.blockID);
        var1.setBlock(var3 + 7, var4 + 1, var5 + 3, 0);
        var1.setBlock(var3 + 7, var4 + 1, var5 + 4, 0);
        var1.setBlock(var3 + 7, var4 + 1, var5 + 5, DivineRPG.iceikaStoneBricks.blockID);
        var1.setBlock(var3 + 7, var4 + 1, var5 + 6, DivineRPG.iceikaStoneBricks.blockID);
        var1.setBlock(var3 + 7, var4 + 1, var5 + 7, DivineRPG.iceikaStoneBricks.blockID);
        var1.setBlock(var3 + 7, var4 + 1, var5 + 9, DivineRPG.iceikaStoneBricks.blockID);
        var1.setBlock(var3 + 7, var4 + 1, var5 + 10, 0);
        var1.setBlock(var3 + 7, var4 + 1, var5 + 11, 0);
        var1.setBlock(var3 + 7, var4 + 1, var5 + 12, 0);
        var1.setBlock(var3 + 7, var4 + 1, var5 + 13, 0);
        var1.setBlock(var3 + 7, var4 + 1, var5 + 14, 0);
        var1.setBlock(var3 + 7, var4 + 1, var5 + 15, 0);
        var1.setBlock(var3 + 7, var4 + 1, var5 + 16, 0);
        var1.setBlock(var3 + 7, var4 + 1, var5 + 17, 0);
        var1.setBlock(var3 + 7, var4 + 1, var5 + 18, 0);
        var1.setBlock(var3 + 7, var4 + 1, var5 + 19, 0);
        var1.setBlock(var3 + 7, var4 + 1, var5 + 20, DivineRPG.iceikaStoneBricks.blockID);
        var1.setBlock(var3 + 7, var4 + 2, var5 + 0, DivineRPG.iceikaStoneBricks.blockID);
        var1.setBlock(var3 + 7, var4 + 2, var5 + 1, DivineRPG.iceikaStoneBricks.blockID);
        var1.setBlock(var3 + 7, var4 + 2, var5 + 2, DivineRPG.iceikaStoneBricks.blockID);
        var1.setBlock(var3 + 7, var4 + 2, var5 + 3, 0);
        var1.setBlock(var3 + 7, var4 + 2, var5 + 4, 0);
        var1.setBlock(var3 + 7, var4 + 2, var5 + 5, DivineRPG.iceikaStoneBricks.blockID);
        var1.setBlock(var3 + 7, var4 + 2, var5 + 6, DivineRPG.iceikaStoneBricks.blockID);
        var1.setBlock(var3 + 7, var4 + 2, var5 + 7, DivineRPG.iceikaStoneBricks.blockID);
        var1.setBlock(var3 + 7, var4 + 2, var5 + 9, DivineRPG.iceikaStoneBricks.blockID);
        var1.setBlock(var3 + 7, var4 + 2, var5 + 10, 0);
        var1.setBlock(var3 + 7, var4 + 2, var5 + 11, 0);
        var1.setBlock(var3 + 7, var4 + 2, var5 + 12, 0);
        var1.setBlock(var3 + 7, var4 + 2, var5 + 13, 0);
        var1.setBlock(var3 + 7, var4 + 2, var5 + 14, 0);
        var1.setBlock(var3 + 7, var4 + 2, var5 + 15, 0);
        var1.setBlock(var3 + 7, var4 + 2, var5 + 16, 0);
        var1.setBlock(var3 + 7, var4 + 2, var5 + 17, 0);
        var1.setBlock(var3 + 7, var4 + 2, var5 + 18, 0);
        var1.setBlock(var3 + 7, var4 + 2, var5 + 19, 0);
        var1.setBlock(var3 + 7, var4 + 2, var5 + 20, DivineRPG.iceikaStoneBricks.blockID);
        var1.setBlock(var3 + 7, var4 + 3, var5 + 0, DivineRPG.iceikaStoneBricks.blockID);
        var1.setBlock(var3 + 7, var4 + 3, var5 + 1, DivineRPG.iceikaStoneBricks.blockID);
        var1.setBlock(var3 + 7, var4 + 3, var5 + 2, DivineRPG.iceikaStoneBricks.blockID);
        var1.setBlock(var3 + 7, var4 + 3, var5 + 3, 0);
        var1.setBlock(var3 + 7, var4 + 3, var5 + 4, 0);
        var1.setBlock(var3 + 7, var4 + 3, var5 + 5, DivineRPG.iceikaStoneBricks.blockID);
        var1.setBlock(var3 + 7, var4 + 3, var5 + 6, DivineRPG.iceikaStoneBricks.blockID);
        var1.setBlock(var3 + 7, var4 + 3, var5 + 7, DivineRPG.iceikaStoneBricks.blockID);
        var1.setBlock(var3 + 7, var4 + 3, var5 + 9, DivineRPG.iceikaStoneBricks.blockID);
        var1.setBlock(var3 + 7, var4 + 3, var5 + 10, 0);
        var1.setBlock(var3 + 7, var4 + 3, var5 + 11, 0);
        var1.setBlock(var3 + 7, var4 + 3, var5 + 12, 0);
        var1.setBlock(var3 + 7, var4 + 3, var5 + 13, 0);
        var1.setBlock(var3 + 7, var4 + 3, var5 + 14, 0);
        var1.setBlock(var3 + 7, var4 + 3, var5 + 15, 0);
        var1.setBlock(var3 + 7, var4 + 3, var5 + 16, 0);
        var1.setBlock(var3 + 7, var4 + 3, var5 + 17, 0);
        var1.setBlock(var3 + 7, var4 + 3, var5 + 18, 0);
        var1.setBlock(var3 + 7, var4 + 3, var5 + 19, 0);
        var1.setBlock(var3 + 7, var4 + 3, var5 + 20, DivineRPG.iceikaStoneBricks.blockID);
        var1.setBlock(var3 + 7, var4 + 4, var5 + 3, DivineRPG.iceikaStoneBricks.blockID);
        var1.setBlock(var3 + 7, var4 + 4, var5 + 4, DivineRPG.iceikaStoneBricks.blockID);
        var1.setBlock(var3 + 7, var4 + 4, var5 + 10, DivineRPG.iceikaStoneBricks.blockID);
        var1.setBlock(var3 + 7, var4 + 4, var5 + 11, DivineRPG.iceikaStoneBricks.blockID);
        var1.setBlock(var3 + 7, var4 + 4, var5 + 12, DivineRPG.iceikaStoneBricks.blockID);
        var1.setBlock(var3 + 7, var4 + 4, var5 + 13, DivineRPG.iceikaStoneBricks.blockID);
        var1.setBlock(var3 + 7, var4 + 4, var5 + 14, DivineRPG.iceikaStoneBricks.blockID);
        var1.setBlock(var3 + 7, var4 + 4, var5 + 15, DivineRPG.iceikaStoneBricks.blockID);
        var1.setBlock(var3 + 7, var4 + 4, var5 + 16, DivineRPG.iceikaStoneBricks.blockID);
        var1.setBlock(var3 + 7, var4 + 4, var5 + 17, DivineRPG.iceikaStoneBricks.blockID);
        var1.setBlock(var3 + 7, var4 + 4, var5 + 18, DivineRPG.iceikaStoneBricks.blockID);
        var1.setBlock(var3 + 7, var4 + 4, var5 + 19, DivineRPG.iceikaStoneBricks.blockID);
        var1.setBlock(var3 + 8, var4 + 0, var5 + 2, DivineRPG.iceikaStoneBricks.blockID);
        var1.setBlock(var3 + 8, var4 + 0, var5 + 3, DivineRPG.iceikaMossyCobble.blockID);
        var1.setBlock(var3 + 8, var4 + 0, var5 + 4, DivineRPG.iceikaMossyCobble.blockID);
        var1.setBlock(var3 + 8, var4 + 0, var5 + 5, DivineRPG.iceikaStoneBricks.blockID);
        var1.setBlock(var3 + 8, var4 + 0, var5 + 9, DivineRPG.iceikaStoneBricks.blockID);
        var1.setBlock(var3 + 8, var4 + 0, var5 + 10, DivineRPG.iceikaMossyCobble.blockID);
        var1.setBlock(var3 + 8, var4 + 0, var5 + 11, DivineRPG.iceikaMossyCobble.blockID);
        var1.setBlock(var3 + 8, var4 + 0, var5 + 12, DivineRPG.iceikaStoneBricks.blockID);
        var1.setBlock(var3 + 8, var4 + 0, var5 + 13, DivineRPG.iceikaStoneBricks.blockID);
        var1.setBlock(var3 + 8, var4 + 0, var5 + 14, DivineRPG.iceikaStoneBricks.blockID);
        var1.setBlock(var3 + 8, var4 + 0, var5 + 15, DivineRPG.iceikaStoneBricks.blockID);
        var1.setBlock(var3 + 8, var4 + 0, var5 + 16, DivineRPG.iceikaStoneBricks.blockID);
        var1.setBlock(var3 + 8, var4 + 0, var5 + 17, DivineRPG.iceikaStoneBricks.blockID);
        var1.setBlock(var3 + 8, var4 + 0, var5 + 18, DivineRPG.iceikaStoneBricks.blockID);
        var1.setBlock(var3 + 8, var4 + 0, var5 + 19, DivineRPG.iceikaStoneBricks.blockID);
        var1.setBlock(var3 + 8, var4 + 0, var5 + 20, DivineRPG.iceikaStoneBricks.blockID);
        var1.setBlock(var3 + 8, var4 + 1, var5 + 2, DivineRPG.iceikaStoneBricks.blockID);
        var1.setBlock(var3 + 8, var4 + 1, var5 + 3, 0);
        var1.setBlock(var3 + 8, var4 + 1, var5 + 4, 0);
        var1.setBlock(var3 + 8, var4 + 1, var5 + 5, DivineRPG.iceikaStoneBricks.blockID);
        var1.setBlock(var3 + 8, var4 + 1, var5 + 9, DivineRPG.iceikaStoneBricks.blockID);
        var1.setBlock(var3 + 8, var4 + 1, var5 + 10, 0);
        var1.setBlock(var3 + 8, var4 + 1, var5 + 11, 0);
        var1.setBlock(var3 + 8, var4 + 1, var5 + 12, DivineRPG.iceikaStoneBricks.blockID);
        var1.setBlock(var3 + 8, var4 + 1, var5 + 13, DivineRPG.iceikaStoneBricks.blockID);
        var1.setBlock(var3 + 8, var4 + 1, var5 + 14, DivineRPG.iceikaStoneBricks.blockID);
        var1.setBlock(var3 + 8, var4 + 1, var5 + 15, DivineRPG.iceikaStoneBricks.blockID);
        var1.setBlock(var3 + 8, var4 + 1, var5 + 16, DivineRPG.iceikaStoneBricks.blockID);
        var1.setBlock(var3 + 8, var4 + 1, var5 + 17, DivineRPG.iceikaStoneBricks.blockID);
        var1.setBlock(var3 + 8, var4 + 1, var5 + 18, DivineRPG.iceikaStoneBricks.blockID);
        var1.setBlock(var3 + 8, var4 + 1, var5 + 19, DivineRPG.iceikaStoneBricks.blockID);
        var1.setBlock(var3 + 8, var4 + 1, var5 + 20, DivineRPG.iceikaStoneBricks.blockID);
        var1.setBlock(var3 + 8, var4 + 2, var5 + 2, DivineRPG.iceikaStoneBricks.blockID);
        var1.setBlock(var3 + 8, var4 + 2, var5 + 3, 0);
        var1.setBlock(var3 + 8, var4 + 2, var5 + 4, 0);
        var1.setBlock(var3 + 8, var4 + 2, var5 + 5, DivineRPG.iceikaStoneBricks.blockID);
        var1.setBlock(var3 + 8, var4 + 2, var5 + 9, DivineRPG.iceikaStoneBricks.blockID);
        var1.setBlock(var3 + 8, var4 + 2, var5 + 10, 0);
        var1.setBlock(var3 + 8, var4 + 2, var5 + 11, 0);
        var1.setBlock(var3 + 8, var4 + 2, var5 + 12, DivineRPG.iceikaStoneBricks.blockID);
        var1.setBlock(var3 + 8, var4 + 2, var5 + 13, DivineRPG.iceikaStoneBricks.blockID);
        var1.setBlock(var3 + 8, var4 + 2, var5 + 14, DivineRPG.iceikaStoneBricks.blockID);
        var1.setBlock(var3 + 8, var4 + 2, var5 + 15, DivineRPG.iceikaStoneBricks.blockID);
        var1.setBlock(var3 + 8, var4 + 2, var5 + 16, DivineRPG.iceikaStoneBricks.blockID);
        var1.setBlock(var3 + 8, var4 + 2, var5 + 17, DivineRPG.iceikaStoneBricks.blockID);
        var1.setBlock(var3 + 8, var4 + 2, var5 + 18, DivineRPG.iceikaStoneBricks.blockID);
        var1.setBlock(var3 + 8, var4 + 2, var5 + 19, DivineRPG.iceikaStoneBricks.blockID);
        var1.setBlock(var3 + 8, var4 + 2, var5 + 20, DivineRPG.iceikaStoneBricks.blockID);
        var1.setBlock(var3 + 8, var4 + 3, var5 + 2, DivineRPG.iceikaStoneBricks.blockID);
        var1.setBlock(var3 + 8, var4 + 3, var5 + 3, 0);
        var1.setBlock(var3 + 8, var4 + 3, var5 + 4, 0);
        var1.setBlock(var3 + 8, var4 + 3, var5 + 5, DivineRPG.iceikaStoneBricks.blockID);
        var1.setBlock(var3 + 8, var4 + 3, var5 + 9, DivineRPG.iceikaStoneBricks.blockID);
        var1.setBlock(var3 + 8, var4 + 3, var5 + 10, 0);
        var1.setBlock(var3 + 8, var4 + 3, var5 + 11, 0);
        var1.setBlock(var3 + 8, var4 + 3, var5 + 12, DivineRPG.iceikaStoneBricks.blockID);
        var1.setBlock(var3 + 8, var4 + 3, var5 + 13, DivineRPG.iceikaStoneBricks.blockID);
        var1.setBlock(var3 + 8, var4 + 3, var5 + 14, DivineRPG.iceikaStoneBricks.blockID);
        var1.setBlock(var3 + 8, var4 + 3, var5 + 15, DivineRPG.iceikaStoneBricks.blockID);
        var1.setBlock(var3 + 8, var4 + 3, var5 + 16, DivineRPG.iceikaStoneBricks.blockID);
        var1.setBlock(var3 + 8, var4 + 3, var5 + 17, DivineRPG.iceikaStoneBricks.blockID);
        var1.setBlock(var3 + 8, var4 + 3, var5 + 18, DivineRPG.iceikaStoneBricks.blockID);
        var1.setBlock(var3 + 8, var4 + 3, var5 + 19, DivineRPG.iceikaStoneBricks.blockID);
        var1.setBlock(var3 + 8, var4 + 3, var5 + 20, DivineRPG.iceikaStoneBricks.blockID);
        var1.setBlock(var3 + 8, var4 + 4, var5 + 3, DivineRPG.iceikaStoneBricks.blockID);
        var1.setBlock(var3 + 8, var4 + 4, var5 + 4, DivineRPG.iceikaStoneBricks.blockID);
        var1.setBlock(var3 + 8, var4 + 4, var5 + 10, DivineRPG.iceikaStoneBricks.blockID);
        var1.setBlock(var3 + 8, var4 + 4, var5 + 11, DivineRPG.iceikaStoneBricks.blockID);
        var1.setBlock(var3 + 9, var4 + 0, var5 + 2, DivineRPG.iceikaStoneBricks.blockID);
        var1.setBlock(var3 + 9, var4 + 0, var5 + 3, DivineRPG.iceikaMossyCobble.blockID);
        var1.setBlock(var3 + 9, var4 + 0, var5 + 4, DivineRPG.iceikaMossyCobble.blockID);
        var1.setBlock(var3 + 9, var4 + 0, var5 + 5, DivineRPG.iceikaStoneBricks.blockID);
        var1.setBlock(var3 + 9, var4 + 0, var5 + 6, DivineRPG.iceikaStoneBricks.blockID);
        var1.setBlock(var3 + 9, var4 + 0, var5 + 7, DivineRPG.iceikaStoneBricks.blockID);
        var1.setBlock(var3 + 9, var4 + 0, var5 + 8, DivineRPG.iceikaStoneBricks.blockID);
        var1.setBlock(var3 + 9, var4 + 0, var5 + 9, DivineRPG.iceikaStoneBricks.blockID);
        var1.setBlock(var3 + 9, var4 + 0, var5 + 10, DivineRPG.iceikaMossyCobble.blockID);
        var1.setBlock(var3 + 9, var4 + 0, var5 + 11, DivineRPG.iceikaMossyCobble.blockID);
        var1.setBlock(var3 + 9, var4 + 0, var5 + 12, DivineRPG.iceikaStoneBricks.blockID);
        var1.setBlock(var3 + 9, var4 + 1, var5 + 2, DivineRPG.iceikaStoneBricks.blockID);
        var1.setBlock(var3 + 9, var4 + 1, var5 + 3, 0);
        var1.setBlock(var3 + 9, var4 + 1, var5 + 4, 0);
        var1.setBlock(var3 + 9, var4 + 1, var5 + 5, DivineRPG.iceikaStoneBricks.blockID);
        var1.setBlock(var3 + 9, var4 + 1, var5 + 6, DivineRPG.iceikaStoneBricks.blockID);
        var1.setBlock(var3 + 9, var4 + 1, var5 + 7, DivineRPG.iceikaStoneBricks.blockID);
        var1.setBlock(var3 + 9, var4 + 1, var5 + 8, DivineRPG.iceikaStoneBricks.blockID);
        var1.setBlock(var3 + 9, var4 + 1, var5 + 9, DivineRPG.iceikaStoneBricks.blockID);
        var1.setBlock(var3 + 9, var4 + 1, var5 + 10, 0);
        var1.setBlock(var3 + 9, var4 + 1, var5 + 11, 0);
        var1.setBlock(var3 + 9, var4 + 1, var5 + 12, DivineRPG.iceikaStoneBricks.blockID);
        var1.setBlock(var3 + 9, var4 + 2, var5 + 2, DivineRPG.iceikaStoneBricks.blockID);
        var1.setBlock(var3 + 9, var4 + 2, var5 + 3, 0);
        var1.setBlock(var3 + 9, var4 + 2, var5 + 4, 0);
        var1.setBlock(var3 + 9, var4 + 2, var5 + 5, DivineRPG.iceikaStoneBricks.blockID);
        var1.setBlock(var3 + 9, var4 + 2, var5 + 6, DivineRPG.iceikaStoneBricks.blockID);
        var1.setBlock(var3 + 9, var4 + 2, var5 + 7, DivineRPG.iceikaStoneBricks.blockID);
        var1.setBlock(var3 + 9, var4 + 2, var5 + 8, DivineRPG.iceikaStoneBricks.blockID);
        var1.setBlock(var3 + 9, var4 + 2, var5 + 9, DivineRPG.iceikaStoneBricks.blockID);
        var1.setBlock(var3 + 9, var4 + 2, var5 + 10, 0);
        var1.setBlock(var3 + 9, var4 + 2, var5 + 11, 0);
        var1.setBlock(var3 + 9, var4 + 2, var5 + 12, DivineRPG.iceikaStoneBricks.blockID);
        var1.setBlock(var3 + 9, var4 + 3, var5 + 2, DivineRPG.iceikaStoneBricks.blockID);
        var1.setBlock(var3 + 9, var4 + 3, var5 + 3, 0);
        var1.setBlock(var3 + 9, var4 + 3, var5 + 4, 0);
        var1.setBlock(var3 + 9, var4 + 3, var5 + 5, DivineRPG.iceikaStoneBricks.blockID);
        var1.setBlock(var3 + 9, var4 + 3, var5 + 6, DivineRPG.iceikaStoneBricks.blockID);
        var1.setBlock(var3 + 9, var4 + 3, var5 + 7, DivineRPG.iceikaStoneBricks.blockID);
        var1.setBlock(var3 + 9, var4 + 3, var5 + 8, DivineRPG.iceikaStoneBricks.blockID);
        var1.setBlock(var3 + 9, var4 + 3, var5 + 9, DivineRPG.iceikaStoneBricks.blockID);
        var1.setBlock(var3 + 9, var4 + 3, var5 + 10, 0);
        var1.setBlock(var3 + 9, var4 + 3, var5 + 11, 0);
        var1.setBlock(var3 + 9, var4 + 3, var5 + 12, DivineRPG.iceikaStoneBricks.blockID);
        var1.setBlock(var3 + 9, var4 + 4, var5 + 3, DivineRPG.iceikaStoneBricks.blockID);
        var1.setBlock(var3 + 9, var4 + 4, var5 + 4, DivineRPG.iceikaStoneBricks.blockID);
        var1.setBlock(var3 + 9, var4 + 4, var5 + 10, DivineRPG.iceikaStoneBricks.blockID);
        var1.setBlock(var3 + 9, var4 + 4, var5 + 11, DivineRPG.iceikaStoneBricks.blockID);
        var1.setBlock(var3 + 10, var4 + 0, var5 + 2, DivineRPG.iceikaStoneBricks.blockID);
        var1.setBlock(var3 + 10, var4 + 0, var5 + 3, DivineRPG.iceikaMossyCobble.blockID);
        var1.setBlock(var3 + 10, var4 + 0, var5 + 4, DivineRPG.iceikaMossyCobble.blockID);
        var1.setBlock(var3 + 10, var4 + 0, var5 + 5, DivineRPG.iceikaMossyCobble.blockID);
        var1.setBlock(var3 + 10, var4 + 0, var5 + 6, DivineRPG.iceikaMossyCobble.blockID);
        var1.setBlock(var3 + 10, var4 + 0, var5 + 7, DivineRPG.iceikaMossyCobble.blockID);
        var1.setBlock(var3 + 10, var4 + 0, var5 + 8, DivineRPG.iceikaMossyCobble.blockID);
        var1.setBlock(var3 + 10, var4 + 0, var5 + 9, DivineRPG.iceikaMossyCobble.blockID);
        var1.setBlock(var3 + 10, var4 + 0, var5 + 10, DivineRPG.iceikaMossyCobble.blockID);
        var1.setBlock(var3 + 10, var4 + 0, var5 + 11, DivineRPG.iceikaMossyCobble.blockID);
        var1.setBlock(var3 + 10, var4 + 0, var5 + 12, DivineRPG.iceikaStoneBricks.blockID);
        var1.setBlock(var3 + 10, var4 + 1, var5 + 2, DivineRPG.iceikaStoneBricks.blockID);
        var1.setBlock(var3 + 10, var4 + 1, var5 + 3, 0);
        var1.setBlock(var3 + 10, var4 + 1, var5 + 4, 0);
        var1.setBlock(var3 + 10, var4 + 1, var5 + 5, 0);
        var1.setBlock(var3 + 10, var4 + 1, var5 + 6, 0);
        var1.setBlock(var3 + 10, var4 + 1, var5 + 7, 0);
        var1.setBlock(var3 + 10, var4 + 1, var5 + 8, 0);
        var1.setBlock(var3 + 10, var4 + 1, var5 + 9, 0);
        var1.setBlock(var3 + 10, var4 + 1, var5 + 10, 0);
        var1.setBlock(var3 + 10, var4 + 1, var5 + 11, 0);
        var1.setBlock(var3 + 10, var4 + 1, var5 + 12, DivineRPG.iceikaStoneBricks.blockID);
        var1.setBlock(var3 + 10, var4 + 2, var5 + 2, DivineRPG.iceikaStoneBricks.blockID);
        var1.setBlock(var3 + 10, var4 + 2, var5 + 3, 0);
        var1.setBlock(var3 + 10, var4 + 2, var5 + 4, 0);
        var1.setBlock(var3 + 10, var4 + 2, var5 + 5, 0);
        var1.setBlock(var3 + 10, var4 + 2, var5 + 6, 0);
        var1.setBlock(var3 + 10, var4 + 2, var5 + 7, 0);
        var1.setBlock(var3 + 10, var4 + 2, var5 + 8, 0);
        var1.setBlock(var3 + 10, var4 + 2, var5 + 9, 0);
        var1.setBlock(var3 + 10, var4 + 2, var5 + 10, 0);
        var1.setBlock(var3 + 10, var4 + 2, var5 + 11, 0);
        var1.setBlock(var3 + 10, var4 + 2, var5 + 12, DivineRPG.iceikaStoneBricks.blockID);
        var1.setBlock(var3 + 10, var4 + 3, var5 + 2, DivineRPG.iceikaStoneBricks.blockID);
        var1.setBlock(var3 + 10, var4 + 3, var5 + 3, 0);
        var1.setBlock(var3 + 10, var4 + 3, var5 + 4, 0);
        var1.setBlock(var3 + 10, var4 + 3, var5 + 5, 0);
        var1.setBlock(var3 + 10, var4 + 3, var5 + 6, 0);
        var1.setBlock(var3 + 10, var4 + 3, var5 + 7, 0);
        var1.setBlock(var3 + 10, var4 + 3, var5 + 8, 0);
        var1.setBlock(var3 + 10, var4 + 3, var5 + 9, 0);
        var1.setBlock(var3 + 10, var4 + 3, var5 + 10, 0);
        var1.setBlock(var3 + 10, var4 + 3, var5 + 11, 0);
        var1.setBlock(var3 + 10, var4 + 3, var5 + 12, DivineRPG.iceikaStoneBricks.blockID);
        var1.setBlock(var3 + 10, var4 + 4, var5 + 3, DivineRPG.iceikaStoneBricks.blockID);
        var1.setBlock(var3 + 10, var4 + 4, var5 + 4, DivineRPG.iceikaStoneBricks.blockID);
        var1.setBlock(var3 + 10, var4 + 4, var5 + 5, DivineRPG.iceikaStoneBricks.blockID);
        var1.setBlock(var3 + 10, var4 + 4, var5 + 6, DivineRPG.iceikaStoneBricks.blockID);
        var1.setBlock(var3 + 10, var4 + 4, var5 + 7, DivineRPG.iceikaStoneBricks.blockID);
        var1.setBlock(var3 + 10, var4 + 4, var5 + 8, DivineRPG.iceikaStoneBricks.blockID);
        var1.setBlock(var3 + 10, var4 + 4, var5 + 9, DivineRPG.iceikaStoneBricks.blockID);
        var1.setBlock(var3 + 10, var4 + 4, var5 + 10, DivineRPG.iceikaStoneBricks.blockID);
        var1.setBlock(var3 + 10, var4 + 4, var5 + 11, DivineRPG.iceikaStoneBricks.blockID);
        var1.setBlock(var3 + 11, var4 + 0, var5 + 2, DivineRPG.iceikaStoneBricks.blockID);
        var1.setBlock(var3 + 11, var4 + 0, var5 + 3, DivineRPG.iceikaMossyCobble.blockID);
        var1.setBlock(var3 + 11, var4 + 0, var5 + 4, DivineRPG.iceikaMossyCobble.blockID);
        var1.setBlock(var3 + 11, var4 + 0, var5 + 5, DivineRPG.iceikaMossyCobble.blockID);
        var1.setBlock(var3 + 11, var4 + 0, var5 + 6, DivineRPG.iceikaMossyCobble.blockID);
        var1.setBlock(var3 + 11, var4 + 0, var5 + 7, DivineRPG.iceikaMossyCobble.blockID);
        var1.setBlock(var3 + 11, var4 + 0, var5 + 8, DivineRPG.iceikaMossyCobble.blockID);
        var1.setBlock(var3 + 11, var4 + 0, var5 + 9, DivineRPG.iceikaMossyCobble.blockID);
        var1.setBlock(var3 + 11, var4 + 0, var5 + 10, DivineRPG.iceikaMossyCobble.blockID);
        var1.setBlock(var3 + 11, var4 + 0, var5 + 11, DivineRPG.iceikaMossyCobble.blockID);
        var1.setBlock(var3 + 11, var4 + 0, var5 + 12, DivineRPG.iceikaStoneBricks.blockID);
        var1.setBlock(var3 + 11, var4 + 1, var5 + 2, DivineRPG.iceikaStoneBricks.blockID);
        var1.setBlock(var3 + 11, var4 + 1, var5 + 3, 0);
        var1.setBlock(var3 + 11, var4 + 1, var5 + 4, 0);
        var1.setBlock(var3 + 11, var4 + 1, var5 + 5, 0);
        var1.setBlock(var3 + 11, var4 + 1, var5 + 6, 0);
        var1.setBlock(var3 + 11, var4 + 1, var5 + 7, 0);
        var1.setBlock(var3 + 11, var4 + 1, var5 + 8, 0);
        var1.setBlock(var3 + 11, var4 + 1, var5 + 9, 0);
        var1.setBlock(var3 + 11, var4 + 1, var5 + 10, 0);
        var1.setBlock(var3 + 11, var4 + 1, var5 + 11, 0);
        var1.setBlock(var3 + 11, var4 + 1, var5 + 12, DivineRPG.iceikaStoneBricks.blockID);
        var1.setBlock(var3 + 11, var4 + 2, var5 + 2, DivineRPG.iceikaStoneBricks.blockID);
        var1.setBlock(var3 + 11, var4 + 2, var5 + 3, 0);
        var1.setBlock(var3 + 11, var4 + 2, var5 + 4, 0);
        var1.setBlock(var3 + 11, var4 + 2, var5 + 5, 0);
        var1.setBlock(var3 + 11, var4 + 2, var5 + 6, 0);
        var1.setBlock(var3 + 11, var4 + 2, var5 + 7, 0);
        var1.setBlock(var3 + 11, var4 + 2, var5 + 8, 0);
        var1.setBlock(var3 + 11, var4 + 2, var5 + 9, 0);
        var1.setBlock(var3 + 11, var4 + 2, var5 + 10, 0);
        var1.setBlock(var3 + 11, var4 + 2, var5 + 11, 0);
        var1.setBlock(var3 + 11, var4 + 2, var5 + 12, DivineRPG.iceikaStoneBricks.blockID);
        var1.setBlock(var3 + 11, var4 + 3, var5 + 2, DivineRPG.iceikaStoneBricks.blockID);
        var1.setBlock(var3 + 11, var4 + 3, var5 + 3, 0);
        var1.setBlock(var3 + 11, var4 + 3, var5 + 4, 0);
        var1.setBlock(var3 + 11, var4 + 3, var5 + 5, 0);
        var1.setBlock(var3 + 11, var4 + 3, var5 + 6, 0);
        var1.setBlock(var3 + 11, var4 + 3, var5 + 7, 0);
        var1.setBlock(var3 + 11, var4 + 3, var5 + 8, 0);
        var1.setBlock(var3 + 11, var4 + 3, var5 + 9, 0);
        var1.setBlock(var3 + 11, var4 + 3, var5 + 10, 0);
        var1.setBlock(var3 + 11, var4 + 3, var5 + 11, 0);
        var1.setBlock(var3 + 11, var4 + 3, var5 + 12, DivineRPG.iceikaStoneBricks.blockID);
        var1.setBlock(var3 + 11, var4 + 4, var5 + 3, DivineRPG.iceikaStoneBricks.blockID);
        var1.setBlock(var3 + 11, var4 + 4, var5 + 4, DivineRPG.iceikaStoneBricks.blockID);
        var1.setBlock(var3 + 11, var4 + 4, var5 + 5, DivineRPG.iceikaStoneBricks.blockID);
        var1.setBlock(var3 + 11, var4 + 4, var5 + 6, DivineRPG.iceikaStoneBricks.blockID);
        var1.setBlock(var3 + 11, var4 + 4, var5 + 7, DivineRPG.iceikaStoneBricks.blockID);
        var1.setBlock(var3 + 11, var4 + 4, var5 + 8, DivineRPG.iceikaStoneBricks.blockID);
        var1.setBlock(var3 + 11, var4 + 4, var5 + 9, DivineRPG.iceikaStoneBricks.blockID);
        var1.setBlock(var3 + 11, var4 + 4, var5 + 10, DivineRPG.iceikaStoneBricks.blockID);
        var1.setBlock(var3 + 11, var4 + 4, var5 + 11, DivineRPG.iceikaStoneBricks.blockID);
        var1.setBlock(var3 + 12, var4 + 0, var5 + 2, DivineRPG.iceikaStoneBricks.blockID);
        var1.setBlock(var3 + 12, var4 + 0, var5 + 3, DivineRPG.iceikaStoneBricks.blockID);
        var1.setBlock(var3 + 12, var4 + 0, var5 + 4, DivineRPG.iceikaStoneBricks.blockID);
        var1.setBlock(var3 + 12, var4 + 0, var5 + 5, DivineRPG.iceikaStoneBricks.blockID);
        var1.setBlock(var3 + 12, var4 + 0, var5 + 6, DivineRPG.iceikaStoneBricks.blockID);
        var1.setBlock(var3 + 12, var4 + 0, var5 + 7, DivineRPG.iceikaStoneBricks.blockID);
        var1.setBlock(var3 + 12, var4 + 0, var5 + 8, DivineRPG.iceikaStoneBricks.blockID);
        var1.setBlock(var3 + 12, var4 + 0, var5 + 9, DivineRPG.iceikaStoneBricks.blockID);
        var1.setBlock(var3 + 12, var4 + 0, var5 + 10, DivineRPG.iceikaStoneBricks.blockID);
        var1.setBlock(var3 + 12, var4 + 0, var5 + 11, DivineRPG.iceikaStoneBricks.blockID);
        var1.setBlock(var3 + 12, var4 + 0, var5 + 12, DivineRPG.iceikaStoneBricks.blockID);
        var1.setBlock(var3 + 12, var4 + 1, var5 + 2, DivineRPG.iceikaStoneBricks.blockID);
        var1.setBlock(var3 + 12, var4 + 1, var5 + 3, DivineRPG.iceikaStoneBricks.blockID);
        var1.setBlock(var3 + 12, var4 + 1, var5 + 4, DivineRPG.iceikaStoneBricks.blockID);
        var1.setBlock(var3 + 12, var4 + 1, var5 + 5, DivineRPG.iceikaStoneBricks.blockID);
        var1.setBlock(var3 + 12, var4 + 1, var5 + 6, DivineRPG.iceikaStoneBricks.blockID);
        var1.setBlock(var3 + 12, var4 + 1, var5 + 7, DivineRPG.iceikaStoneBricks.blockID);
        var1.setBlock(var3 + 12, var4 + 1, var5 + 8, DivineRPG.iceikaStoneBricks.blockID);
        var1.setBlock(var3 + 12, var4 + 1, var5 + 9, DivineRPG.iceikaStoneBricks.blockID);
        var1.setBlock(var3 + 12, var4 + 1, var5 + 10, DivineRPG.iceikaStoneBricks.blockID);
        var1.setBlock(var3 + 12, var4 + 1, var5 + 11, DivineRPG.iceikaStoneBricks.blockID);
        var1.setBlock(var3 + 12, var4 + 1, var5 + 12, DivineRPG.iceikaStoneBricks.blockID);
        var1.setBlock(var3 + 12, var4 + 2, var5 + 2, DivineRPG.iceikaStoneBricks.blockID);
        var1.setBlock(var3 + 12, var4 + 2, var5 + 3, DivineRPG.iceikaStoneBricks.blockID);
        var1.setBlock(var3 + 12, var4 + 2, var5 + 4, DivineRPG.iceikaStoneBricks.blockID);
        var1.setBlock(var3 + 12, var4 + 2, var5 + 5, DivineRPG.iceikaStoneBricks.blockID);
        var1.setBlock(var3 + 12, var4 + 2, var5 + 6, DivineRPG.iceikaStoneBricks.blockID);
        var1.setBlock(var3 + 12, var4 + 2, var5 + 7, DivineRPG.iceikaStoneBricks.blockID);
        var1.setBlock(var3 + 12, var4 + 2, var5 + 8, DivineRPG.iceikaStoneBricks.blockID);
        var1.setBlock(var3 + 12, var4 + 2, var5 + 9, DivineRPG.iceikaStoneBricks.blockID);
        var1.setBlock(var3 + 12, var4 + 2, var5 + 10, DivineRPG.iceikaStoneBricks.blockID);
        var1.setBlock(var3 + 12, var4 + 2, var5 + 11, DivineRPG.iceikaStoneBricks.blockID);
        var1.setBlock(var3 + 12, var4 + 2, var5 + 12, DivineRPG.iceikaStoneBricks.blockID);
        var1.setBlock(var3 + 12, var4 + 3, var5 + 2, DivineRPG.iceikaStoneBricks.blockID);
        var1.setBlock(var3 + 12, var4 + 3, var5 + 3, DivineRPG.iceikaStoneBricks.blockID);
        var1.setBlock(var3 + 12, var4 + 3, var5 + 4, DivineRPG.iceikaStoneBricks.blockID);
        var1.setBlock(var3 + 12, var4 + 3, var5 + 5, DivineRPG.iceikaStoneBricks.blockID);
        var1.setBlock(var3 + 12, var4 + 3, var5 + 6, DivineRPG.iceikaStoneBricks.blockID);
        var1.setBlock(var3 + 12, var4 + 3, var5 + 7, DivineRPG.iceikaStoneBricks.blockID);
        var1.setBlock(var3 + 12, var4 + 3, var5 + 8, DivineRPG.iceikaStoneBricks.blockID);
        var1.setBlock(var3 + 12, var4 + 3, var5 + 9, DivineRPG.iceikaStoneBricks.blockID);
        var1.setBlock(var3 + 12, var4 + 3, var5 + 10, DivineRPG.iceikaStoneBricks.blockID);
        var1.setBlock(var3 + 12, var4 + 3, var5 + 11, DivineRPG.iceikaStoneBricks.blockID);
        var1.setBlock(var3 + 12, var4 + 3, var5 + 12, DivineRPG.iceikaStoneBricks.blockID);
        TileEntityIceikaChest var6 = (TileEntityIceikaChest)var1.getBlockTileEntity(var3, var4, var5);

        if (var6 != null)
        {
            var6.setInventorySlotContents(var2.nextInt(var6.getSizeInventory()), new ItemStack(DivineRPG.snowFlake.itemID, 1, 1));
        }

        return true;
    }
}
